Workbook

Sheet 표지
B2: 견 적 서 (BID PRICE PROPOSAL)
B3: 플랜트 EPC 일괄도급(Lump-Sum Turnkey) 입찰 - 샘플 양식
B5: 발주처 (Owner) | C5: ○○화학 주식회사
B6: 프로젝트명 | C6: ○○ 석유화학 공장 증설 EPC 공사
B7: 입찰번호 (ITB No.) | C7: ITB-2026-0123
B8: 공사위치 | C8: 울산광역시 남구 ○○산업단지
B9: 계약방식 | C9: EPC Lump-Sum Turnkey
B10: 공사기간 | C10: 착공 후 24개월 (기계적 준공 기준)
B11: 견적 통화 | C11: KRW (외화 기자재는 '가정' 시트 환율로 환산)
B12: 견적 기준일 | C12: 2026-10-16
B13: 견적 유효기간 | C13: 제출일로부터 90일
B14: 입찰자 (Bidder) | C14: △△엔지니어링 주식회사
B15: 담당자 / 연락처 | C15: 홍길동 부장 / 02-000-0000
B17: 총 입찰금액 (VAT 별도) | C17: =총괄표!B17 -> 1.0535544e+11
B18: 총 입찰금액 (VAT 포함) | C18: =총괄표!B19 -> 1.1589098e+11
B20: [범례]
B21: 파란 글씨 + 노란 칸 | C21: 직접 입력하는 값 (수량·단가·요율·프로젝트 정보)
B22: 파란 글씨 | C22: 입력값 (샘플 수치 — 실제 견적 시 교체)
B23: 검은 글씨 | C23: 계산식 — 수정하지 마세요
B24: 초록 글씨 | C24: 다른 시트에서 가져온 값
B26: ※ 모든 금액·수량은 양식 이해를 위한 가상의 샘플 값입니다.

Sheet 입찰 체크리스트
A1: EPC 입찰 견적 체크리스트 (Bid Checklist) | I1: 진행 현황
A2: 발주처 문서별 확인 포인트 — 노란 칸(확인상태·견적반영·담당자·확인일·비고)에 입력. 4번째 행은 작성 예시입니다. | I2: 전체 항목 | J2: =COUNTA(D10:D95) -> 74
A3: 근거 수준: A=원문·판매처 확인 / B=2차 자료 확인(원문 대조 권장) / C=조항 미확인 / D=실무 관행(공개 출처 없음). 상세는 '참고문헌' 시트 | I3: 완료 | J3: =COUNTIF(F10:F95,"완료") -> 1
I4: 확인중 | J4: =COUNTIF(F10:F95,"확인중") -> 0
I5: 질의필요 | J5: =COUNTIF(F10:F95,"질의필요") -> 0
I6: 미확인 | J6: =J2-J3-J4-J5-J8 -> 73
I7: 완료율 | J7: =IF(J2-J8=0,0,J3/(J2-J8)) -> 0.013513514 | K7: (해당없음 제외)
I8: 해당없음 | J8: =COUNTIF(F10:F95,"해당없음") -> 0
A9: No | B9: 구분 | C9: 대상 문서 | D9: 체크 항목 | E9: 확인 포인트 / 견적 영향 | F9: 확인상태 | G9: 견적반영 | H9: 담당 | I9: 확인일 | J9: 비고 (근거 조항·질의번호 등) | K9: 출처 · 근거 (참고문헌 시트 ID) | L9: 근거 수준
A10: 1. 입찰 참여 결정 (Go/No-Go)
A11: 1 | B11: 공통 | C11: 내부 검토 | D11: 입찰 자격(PQ) | E11: 실적·면허·재무 요건 충족, JV/컨소시엄 허용 여부 | F11: 완료 | G11: 반영 | H11: 홍길동 | I11: 2026-10-10 | J11: Sec.3.2 PQ 요건 충족 확인 | K11: 업계 실무 관행 / 발주처 문서 확인 대상 | L11: D
A12: 2 | B12: 공통 | C12: 내부 검토 | D12: 발주처 신뢰도 | E12: 재무 상태, 자금 조달 확정 여부, 과거 클레임 이력 | K12: 업계 실무 관행 / 발주처 문서 확인 대상 | L12: D
A13: 3 | B13: 공통 | C13: 내부 검토 | D13: 경쟁 구도 | E13: 경쟁사 수, 예상 낙찰가 수준, 기존 협력사 존재 | K13: 업계 실무 관행 / 발주처 문서 확인 대상 | L13: D
A14: 4 | B14: 공통 | C14: 내부 검토 | D14: 자사 역량·인력 | E14: 해당 공정 경험, PM·설계 인력 투입 가능성, 동시 수주 부담 | K14: 업계 실무 관행 / 발주처 문서 확인 대상 | L14: D
A15: 5 | B15: 공통 | C15: 내부 검토 | D15: 견적 일정 | E15: 입찰 기간 내 벤더 견적 확보 가능 여부(통상 3~6주) | K15: 업계 실무 관행 / 발주처 문서 확인 대상 | L15: D
A16: 6 | B16: 공통 | C16: 내부 검토 | D16: 견적 비용 대비 수주 가능성 | E16: 설계 인력 투입 비용 vs 수주 확률 | K16: 업계 실무 관행 / 발주처 문서 확인 대상 | L16: D
A17: 2. 입찰안내서 (ITB)
A18: 7 | B18: ITB | C18: 입찰안내서 | D18: 일정 | E18: 제출 마감, 질의 마감, 현장설명회(Site Visit) 일자 | K18: 발주처 ITB 원문 확인 대상 (입찰 절차 일반: [R39] FIDIC Procurement Procedures Guide) | L18: D
A19: 8 | B19: ITB | C19: 입찰안내서 | D19: 제출 서류 구성 | E19: 기술/가격 분리 제출, 지정 양식 사용 의무, 부수·서명 | K19: 발주처 ITB 원문 확인 대상 (입찰 절차 일반: [R39] FIDIC Procurement Procedures Guide) | L19: D
A20: 9 | B20: ITB | C20: 입찰안내서 | D20: 평가 방식 | E20: 최저가 vs 종합평가, 기술점수 컷오프 | K20: 발주처 ITB 원문 확인 대상 (입찰 절차 일반: [R39] FIDIC Procurement Procedures Guide) | L20: D
A21: 10 | B21: ITB | C21: 입찰안내서 | D21: 대안·예외 허용 | E21: Alternative 제안, Deviation 기재 허용 여부 | K21: 발주처 ITB 원문 확인 대상 (입찰 절차 일반: [R39] FIDIC Procurement Procedures Guide) | L21: D
A22: 11 | B22: ITB | C22: 입찰안내서 | D22: 입찰보증금 | E22: 금액, 형식, 유효기간 | K22: 발주처 ITB 원문 확인 대상 (입찰 절차 일반: [R39] FIDIC Procurement Procedures Guide) | L22: D
A23: 12 | B23: ITB | C23: 입찰안내서 | D23: 견적 유효기간 | E23: 기간이 길수록 물가·환율 리스크 → 벤더 견적 유효기간과 비교 | K23: 발주처 ITB 원문 확인 대상 (입찰 절차 일반: [R39] FIDIC Procurement Procedures Guide) | L23: D
A24: 13 | B24: ITB | C24: 입찰안내서 | D24: Addendum 반영 | E24: 모든 변경 공지·질의 답변 반영 여부 | K24: 발주처 ITB 원문 확인 대상 (입찰 절차 일반: [R39] FIDIC Procurement Procedures Guide) | L24: D
A25: 3. 계약조건 (GC/SC)
A26: 14 | B26: 계약조건 | C26: 계약 일반/특수조건 | D26: 계약 형태 | E26: Lump-Sum / 단가 / Cost-plus 혼합 여부 | K26: [R38] FIDIC Silver Book 2017 (EPC/Turnkey 표준계약) | L26: A
A27: 15 | B27: 계약조건 | C27: 계약 일반/특수조건 | D27: 지체상금 (Delay LD) | E27: 일 요율 및 상한(Cap) — 상한 없으면 중대 리스크 | K27: [R38] FIDIC Silver Book Cl.8.8 / 공공계약 참고 [R06] 국가계약법 시행규칙 제75조(공사 일 0.5/1000), 시행령 제74조③(상한 30%) | L27: B
A28: 16 | B28: 계약조건 | C28: 계약 일반/특수조건 | D28: 성능보증 LD | E28: 생산량·효율·소비량 미달 배상 기준과 상한, 라이선서 책임 구분 | K28: [R38] FIDIC Silver Book Cl.12 (12.4 성능미달) | L28: A
A29: 17 | B29: 계약조건 | C29: 계약 일반/특수조건 | D29: 책임 한도 | E29: 총 책임 상한(통상 계약금액 100%), 간접손해 면책 조항 | K29: [R38] FIDIC Silver Book Cl.1.14 (책임한도·간접손해 면책) | L29: A
A30: 18 | B30: 계약조건 | C30: 계약 일반/특수조건 | D30: 지급 조건 | E30: 선급금, 마일스톤, 유보금, 지급 기일 → 현금흐름·금융비용 | K30: [R38] FIDIC Silver Book Cl.14 (14.2 선급금) | L30: A
A31: 19 | B31: 계약조건 | C31: 계약 일반/특수조건 | D31: 보증 | E31: 이행·선급·하자보증 비율·기간 → 보증수수료 | K31: [R38] FIDIC Silver Book Cl.4.2 / 공공계약 참고 [R06] 시행령 제50조(계약보증금 10%), 제62조(하자보수보증금 2~10%) | L31: B
A32: 20 | B32: 계약조건 | C32: 계약 일반/특수조건 | D32: 하자보증 기간 | E32: 기간·기산점, 수리부품 재보증 조항 | K32: [R38] FIDIC Silver Book Cl.11 (11.3 DNP 연장) | L32: A
A33: 21 | B33: 계약조건 | C33: 계약 일반/특수조건 | D33: 물가·환율 조정 | E33: Escalation 인정 여부, 환율 리스크 부담 주체 | K33: [R38] FIDIC Silver Book Cl.13.7 (비용변동 조정) | L33: A
A34: 22 | B34: 계약조건 | C34: 계약 일반/특수조건 | D34: 설계변경 | E34: 변경 절차, 비용·공기 인정 방식 | K34: [R38] FIDIC Silver Book Cl.13 (13.3 번호는 2차 확인) | L34: B
A35: 23 | B35: 계약조건 | C35: 계약 일반/특수조건 | D35: 불가항력 | E35: 범위, 공기연장만인지 비용도 인정하는지 | K35: [R38] FIDIC Silver Book Cl.18 (예외적 사건) | L35: A
A36: 24 | B36: 계약조건 | C36: 계약 일반/특수조건 | D36: 세금·관세 | E36: 부담 주체, 면세 여부, 해외 현지세 | K36: [R38] FIDIC Silver Book Cl.13.6 (법령 변경) / 발주처 계약서 확인 | L36: D
A37: 25 | B37: 계약조건 | C37: 계약 일반/특수조건 | D37: 보험 | E37: 시공사 부보 범위(CAR/EAR, 배상책임), 부보 금액 | K37: 발주처 계약서 보험 조항 확인 대상 | L37: D
... A39: 27 | B39: 계약조건 | C39: 계약 일반/특수조건 | D39: 문서 우선순위 | E39: 사양서·도면·계약조건 상충 시 우선순위 조항 | K39: [R38] FIDIC Silver Book Cl.1.5 | L39: A
A40: 4. 업무 범위서 (Scope of Work)
A41: 28 | B41: SOW | C41: 업무 범위서 | D41: Battery Limit | E41: 범위 경계 명확화, Tie-in 포인트 수·위치 | K41: 업계 실무 관행 / 발주처 문서 확인 대상 | L41: D
...

Sheet 석유화학·배관 체크리스트
A1: 석유화학 · 배관 중점 체크리스트 | H1: 진행 현황
A2: 기본 '입찰 체크리스트'에 더해 석유화학 플랜트와 배관 공사에서 비용·공기 누락이 잦은 항목. 영향도: 상(견적 크게 좌우)/중/하 | H2: 전체 항목 | I2: =COUNTA(C12:C66) -> 50
A3: 근거 수준: A=원문·판매처 확인 / B=2차 자료 확인(원문 대조 권장) / C=조항 미확인 / D=실무 관행(공개 출처 없음). 상세는 '참고문헌' 시트 | H3: 영향도 '상' | I3: =COUNTIF(E12:E66,"상") -> 14
H4: 완료 | I4: =COUNTIF(G12:G66,"완료") -> 0
H5: 확인중 | I5: =COUNTIF(G12:G66,"확인중") -> 1
H6: 질의필요 | I6: =COUNTIF(G12:G66,"질의필요") -> 0
H7: 해당없음 | I7: =COUNTIF(G12:G66,"해당없음") -> 0
H8: 완료율 (해당없음 제외) | I8: =IF(I2-I7=0,0,I4/(I2-I7)) -> 0
H9: '상' 항목 완료 | I9: =COUNTIFS(E12:E66,"상",G12:G66,"완료") -> 0
A11: No | B11: 분야 | C11: 체크 항목 | D11: 확인 포인트 / 누락 시 리스크 | E11: 영향도 | F11: 견적 반영 위치 | G11: 확인상태 | H11: 견적반영 | I11: 담당 | J11: 비고 (근거 조항·질의번호 등) | K11: 출처 · 근거 (참고문헌 시트 ID) | L11: 근거 수준
A12: A. 석유화학 공정·법규 특성
A13: 1 | B13: 공정 | C13: 공정 라이선서 요구사항 | D13: 라이선서 표준·검토 절차, 라이선서 승인 필요 도면 범위 → 설계 MH·일정 | E13: 중 | F13: E | G13: 확인중 | H13: 조건명시 | I13: 김배관 | J13: Spec Sec.4 Sour 서비스 대상 라인 질의 예정 | K13: 라이선서 계약·설계 패키지 확인 대상 | L13: D
A14: 2 | B14: 공정 | C14: 고온 수소 · 부식 환경 | D14: HTHA(Nelson Curve), Sour(H2S) 서비스 NACE MR0175/MR0103, 염화물 응력부식 → 재질 상향 | E14: 상 | F14: P / C | K14: [R15] API RP 941 8th (Nelson Curve), [R13] MR0175-2021, [R14] MR0103-2015, [R16] API RP 571 3rd | L14: A
A15: 3 | B15: 공정 | C15: 저온·극저온 서비스 | D15: 에틸렌·프로필렌 등 저온 라인: 충격시험(Impact Test) 재질, LTCS/SS 적용 | E15: 상 | F15: P / C | K15: [R12] ASME B31.3 323.2.2 / 323.3 (저온 충격시험) | L15: B
A16: 4 | B16: 공정 | C16: Fouling · 폴리머 서비스 | D16: 플러싱 연결부, 청소용 플랜지, Jacketed 배관 필요 여부 | E16: 중 | F16: E / C | K16: 업계 실무 관행 / 발주처 문서 확인 대상 | L16: D
A17: 5 | B17: 공정 | C17: Flare · Relief 시스템 | D17: PSV 용량 검토, Flare Header 연결 Tie-in, 기존 Flare 용량 여유 | E17: 상 | F17: E / C | K17: [R24] API Std 521 7th, [R25] API Std 537 | L17: A
A18: 6 | B18: 법규 | C18: PSM (공정안전관리, 산업안전보건법) | D18: 공정안전보고서(PSR) 작성·심사 지원 범위와 일정 | E18: 중 | F18: E / 간접 | K18: [R04] 산안법 제44조, 시행령 제43조, 시행규칙 제51조(착공 30일 전 제출) | L18: B
A19: 7 | B19: 법규 | C19: 고압가스안전관리법 (KGS) | D19: 설계 단계 검사·완성검사 일정, KGS Code 적용 배관 범위 | E19: 중 | F19: E / C / 일정 | K19: [R07] 고압가스법 제16조 (중간·완성검사), [R11] KGS Code (명칭 미확인) | L19: B
A20: 8 | B20: 법규 | C20: 화학물질관리법 (화관법) | D20: 화학사고예방관리계획서(2021.4 장외영향평가·위해관리계획서 통합), 취급시설 기준(누출 감지·방류벽) 반영 | E20: 중 | F20: E / C | K20: [R03] 화관법 제23조 (화학사고예방관리계획서), 제24조 (취급시설 기준) | L20: B
A21: 9 | B21: 법규 | C21: 위험물안전관리법 · 소방 | D21: 탱크·저장소 허가, 소방설비 범위 구분 | E21: 중 | F21: E / C | K21: [R01] 위험물법 제8·9조, [R02] 시행규칙 별표6 | L21: B
A22: 10 | B22: 법규 | C22: 환경 (대기·수질·폐기물) | D22: 배출시설 인허가, 시험수·세정 폐수 처리 비용 | E22: 하 | F22: 간접 | K22: [R08] 대기환경보전법 시행규칙 별표16 (VOC) / 수질·폐기물은 지자체 확인 | L22: B
A23: 11 | B23: 안전설비 | C23: 위험지역 구분 (Hazardous Area) | D23: Zone 구분에 따른 방폭 기기·케이블 사양 상향 | E23: 중 | F23: P | K23: [R26] IEC 60079-10-1 Ed.3.0, [R27] API RP 505 (2025) | L23: A
A24: 12 | B24: 안전설비 | C24: Fire & Gas · SIS | D24: F&G 감지기 수, SIL 검증, SIS 독립성 요구 | E24: 중 | F24: E / P | K24: 업계 실무 관행 / 발주처 문서 확인 대상 | L24: D
A25: 13 | B25: 안전설비 | C25: Fireproofing | D25: 파이프랙·구조물 내화피복 범위(높이 기준) | E25: 중 | F25: C | K25: [R23] API RP 2218 3rd | L25: A
A26: B. 배관 설계·자재
A27: 14 | B27: 설계 | C27: Piping Class / Material Spec | D27: 발주처 Piping Class 수, 재질 종류(CS·SS·Duplex·합금·Lined) → 단가·생산성 좌우 | E27: 상 | F27: E / P | K27: 발주처 Piping Material Spec / [R12] ASME B31.3 | L27: D
A28: 15 | B28: 설계 | C28: MTO 정확도 · 할증률 | D28: FEED 수준별 물량 할증(Growth), 소구경 배관 누락 경향 반영 | E28: 상 | F28: P / C | K28: 실무 관행 (FEED 수준과 연동: [R29] AACE 18R-97) | L28: D
A29: 16 | B29: 설계 | C29: 응력해석 대상 라인 | D29: Critical Line 수, 고온·대구경·회전기기 연결 라인 → 설계 MH·특수 서포트 | E29: 중 | F29: E | K29: [R12] ASME B31.3 Ch.II 유연성 해석 (319, 조항 번호 미확인) | L29: C
A30: 17 | B30: 설계 | C30: 특수 서포트 | D30: Spring Hanger, Snubber, Pipe Shoe 특수 사양 → 별도 구매 품목 | E30: 중 | F30: P | K30: 업계 실무 관행 / 발주처 문서 확인 대상 | L30: D
A31: 18 | B31: 설계 | C31: Expansion Joint · 특수 품목 | D31: 벨로즈, 스트레이너, 스팀 트랩, 사이트 글라스 등 Specialty Item 목록 | E31: 중 | F31: P | K31: 업계 실무 관행 / 발주처 문서 확인 대상 | L31: D
A32: 19 | B32: 설계 | C32: Heat Tracing | D32: Steam/Electric Tracing 범위 → 배관·전기 물량 동시 증가 | E32: 중 | F32: P / C | K32: 업계 실무 관행 / 발주처 문서 확인 대상 | L32: D
A33: 20 | B33: 설계 | C33: 지하 배관 | D33: CS 외부 코팅·전기방식(CP), HDPE/GRP 소방·배수 배관, 굴착 범위 | E33: 중 | F33: P / C | K33: 업계 실무 관행 / 발주처 문서 확인 대상 | L33: D
A34: 21 | B34: 자재 | C34: 합금·고가 자재 가격 변동 | D34: 니켈·몰리브덴 연동 가격(SS, Duplex, Inconel), 견적 유효기간 리스크 | E34: 상 | F34: P / 예비비 | K34: 업계 실무 관행 / 발주처 문서 확인 대상 | L34: D
A35: 22 | B35: 자재 | C35: 재질 추적성 (Traceability) | D35: MTC(EN 10204 3.1/3.2) 요구, 제3자 입회 → 자재 단가 상승 | E35: 중 | F35: P | K35: [R21] EN 10204:2004 (3.1 / 3.2) | L35: B
A36: 23 | B36: 자재 | C36: 밸브 사양 | D36: API 598 / API 6D 시험, Fire-safe(API 607), Fugitive Emission(ISO 15848) 요구 | E36: 중 | F36: P | K36: [R17] API 598 11th, [R18] API 6D 25th, [R19] API 607 8th, [R20] ISO 15848-1 | L36: A
A37: 24 | B37: 자재 | C37: 볼트·가스켓 | D37: 볼트 재질(B7M/L7 등), Spiral Wound·RTJ 가스켓, 볼트 코팅 사양 | E37: 하 | F37: P | K37: 업계 실무 관행 / 발주처 문서 확인 대상 | L37: D
A38: 25 | B38: 자재 | C38: 자재 여유분 · 잉여 | D38: 현장 Wastage·절단 손실, 잉여 자재 처리 조건 | E38: 하 | F38: P | K38: 업계 실무 관행 / 발주처 문서 확인 대상 | L38: D
A39: C. 배관 제작·시공
A40: 26 | B40: 시공 | C40: Dia-Inch 단가 보정 | D40: 재질·스케줄·구경별 생산성 차이 반영 (아래 보정계수표 참고) | E40: 상 | F40: C | K40: 회사 실적 데이터 (참고서: [R30] Page, 5th Ed. — 수치 미인용) | L40: D
A41: 27 | B41: 시공 | C41: Shop / Field 제작 비율 | D41: Spool 공장 제작 비율, 운송·보관 비용, 현장 제작 시 천막·작업장 | E41: 중 | F41: C / 간접 | K41: 업계 실무 관행 / 발주처 문서 확인 대상 | L41: D
...

Sheet 탱크제작 체크리스트
A1: 저장탱크 제작·설치 체크리스트 | H1: 진행 현황
A2: API 650 / 620 계열 현장 조립식 저장탱크 기준. 영향도: 상(견적 크게 좌우)/중/하. 하단에 강판 물량·수압시험수 개략 산출표 포함 | H2: 전체 항목 | I2: =COUNTA(C12:C78) -> 59
A3: 근거 수준: A=원문·판매처 확인 / B=2차 자료 확인(원문 대조 권장) / C=조항 미확인 / D=실무 관행(공개 출처 없음). 상세는 '참고문헌' 시트 | H3: 영향도 '상' | I3: =COUNTIF(E12:E78,"상") -> 19
H4: 완료 | I4: =COUNTIF(G12:G78,"완료") -> 1
H5: 확인중 | I5: =COUNTIF(G12:G78,"확인중") -> 0
H6: 질의필요 | I6: =COUNTIF(G12:G78,"질의필요") -> 0
H7: 해당없음 | I7: =COUNTIF(G12:G78,"해당없음") -> 0
H8: 완료율 (해당없음 제외) | I8: =IF(I2-I7=0,0,I4/(I2-I7)) -> 0.016949153
H9: '상' 항목 완료 | I9: =COUNTIFS(E12:E78,"상",G12:G78,"완료") -> 1
A11: No | B11: 분야 | C11: 체크 항목 | D11: 확인 포인트 / 누락 시 리스크 | E11: 영향도 | F11: 견적 반영 위치 | G11: 확인상태 | H11: 견적반영 | I11: 담당 | J11: 비고 (근거 조항·질의번호 등) | K11: 출처 · 근거 (참고문헌 시트 ID) | L11: 근거 수준
A12: A. 설계 기준 · 사양
A13: 1 | B13: 설계 | C13: 적용 코드 | D13: API 650(대기압) / API 620(저압) / API 625(냉동) / 발주처 표준, Annex 적용 범위 확인 | E13: 상 | F13: E | G13: 완료 | H13: 반영 | I13: 이탱크 | J13: Spec Sec.2.1 API 650 13th Ed. 적용 확인 | K13: [R32] API 650 14th(2025), [R33] API 620 12th, [R34] API 625 | L13: A
A14: 2 | B14: 설계 | C14: 운전 조건 | D14: 설계압력·진공, 설계온도, 저장물 비중, 충전 높이 → 셸 두께 산정 기준 | E14: 상 | F14: E / P | K14: [R32] API 650 5.6 (셸 설계) | L14: B
A15: 3 | B15: 설계 | C15: 부식 여유 · 재질 | D15: 셸·바닥·지붕별 CA, 재질(A283/A516/A537/SS/LTCS), 저온 시 충격시험 | E15: 상 | F15: P | K15: [R32] API 650 Annex S (SS), Annex X (Duplex), [R33] API 620 Annex R/Q (저온) | L15: B
A16: 4 | B16: 설계 | C16: 셸 두께 산정 방식 | D16: 1-Foot / Variable Design Point 적용 → 강판 물량 차이 | E16: 중 | F16: E / P | K16: [R32] API 650 5.6.3 (1-Foot법, D>61m 불가) / 5.6.4 (Variable Design Point) | L16: B
A17: 5 | B17: 설계 | C17: 내진 · 풍하중 | D17: KDS 내진 기준, API 650 Annex E, 앵커 볼트·앵커 체어 필요 여부, 풍하중 보강링 | E17: 상 | F17: E / P / C | K17: [R32] API 650 Annex E, 5.9, 5.11, 5.12 / [R10] KDS 41 17 00 19.6 | L17: B
A18: 6 | B18: 설계 | C18: 지붕 형식 | D18: Cone / Dome / 외부 부상지붕(EFR) / 내부 부상지붕(IFR) / 알루미늄 돔 | E18: 상 | F18: P / C | K18: [R32] API 650 Annex C (EFR), G (알루미늄 돔), H (IFR) | L18: A
A19: 7 | B19: 설계 | C19: 부상지붕 Seal | D19: 1차·2차 Seal 형식, 배출 기준(VOC) 충족 요구 | E19: 중 | F19: P | K19: [R08] 대기환경보전법 시행규칙 별표16 (VOC Seal), [R32] API 650 Annex C/H | L19: B
A20: 8 | B20: 설계 | C20: 바닥판 형식 | D20: Cone-up / Cone-down, 이중 바닥, 누설 감지 설비, Annular Plate 두께 | E20: 중 | F20: E / P | K20: [R32] API 650 Annex I (누설감지·지반보호) | L20: A
A21: 9 | B21: 설계 | C21: 노즐 · 맨홀 | D21: 노즐 수·구경·Rating, 보강판, 삽입판, 대구경 노즐 PWHT 대상 여부 | E21: 중 | F21: P / C | K21: [R32] API 650 5.7.4.2 (노즐 조립체 열처리) | L21: B
A22: 10 | B22: 설계 | C22: 부속 설비 | D22: 나선계단, 플랫폼, 핸드레일, Gauge Hatch, 통기관, 화염방지기, Breather Valve | E22: 중 | F22: P / C | K22: [R37] API Std 2000 8th (통기) | L22: A
A23: 11 | B23: 설계 | C23: 소방 설비 경계 | D23: 폼 챔버, 냉각 살수 링, 소방 배관 범위 구분 (탱크 업체 vs 소방 업체) | E23: 중 | F23: P / C | K23: 업계 실무 관행 / 발주처 문서 확인 대상 | L23: D
A24: 12 | B24: 설계 | C24: 내부 설비 | D24: Heating Coil, Mixer, Swing Line, Sump, 내부 사다리 | E24: 중 | F24: P / C | K24: 업계 실무 관행 / 발주처 문서 확인 대상 | L24: D
A25: 13 | B25: 설계 | C25: 계장 · 접지 | D25: 레벨계(Radar/Servo), 온도계, 고·저 경보, 접지·피뢰 설비 범위 | E25: 하 | F25: P | K25: 업계 실무 관행 / 발주처 문서 확인 대상 | L25: D
A26: B. 법규 · 인허가
A27: 14 | B27: 법규 | C27: 위험물안전관리법 | D27: 옥외탱크저장소 설치 허가, 보유공지, 방유제 기준 | E27: 상 | F27: E / 일정 | K27: [R02] 위험물법 시행규칙 별표6 (보유공지·방유제) | L27: B
A28: 15 | B28: 법규 | C28: 탱크안전성능검사 | D28: 기초·지반검사, 충수·수압검사, 용접부검사 일정 (한국소방산업기술원) → 공정 연동 | E28: 상 | F28: 일정 / 간접 | K28: [R01] 위험물법 제8조, 시행령 제8조 (기초·지반·용접부: 100만L 이상), 제22조 (한국소방산업기술원) | L28: B
A29: 16 | B29: 법규 | C29: 완공검사 | D29: 완공검사 신청 시점, 검사 지적사항 보완 기간 | E29: 중 | F29: 일정 | K29: [R01] 위험물법 제9조, 시행령 제22조 (50만L 이상 옥외탱크: 기술원) | L29: B
A30: 17 | B30: 법규 | C30: 화관법 · 고압가스 | D30: 유해화학물질 저장 시 화학사고예방관리계획서·취급시설 기준, 압력 저장 시 고압가스법 적용 여부 | E30: 중 | F30: E / C | K30: [R03] 화관법 제24조, [R07] 고압가스법 제16조 | L30: B
A31: 18 | B31: 법규 | C31: 환경 | D31: VOC 배출 기준(부상지붕 Seal), 블라스팅 비산먼지 규제 | E31: 중 | F31: P / C | K31: [R08] 대기환경보전법 시행규칙 별표16 | L31: B
A32: C. 기초 · 토목
A33: 19 | B33: 기초 | C33: 지반조사 · 기초 형식 | D33: 링월(Ringwall) / 매트 / 파일 기초 선택, 연약지반 개량 | E33: 상 | F33: C | K33: [R32] API 650 Annex B | L33: A
A34: 20 | B34: 기초 | C34: 허용 침하 | D34: API 650 Annex B 침하 기준, 수압시험 중 침하 측정 계획 | E34: 상 | F34: C / 리스크 | K34: [R32] API 650 Annex B, [R36] API 653 Annex B (침하 평가) | L34: B
A35: 21 | B35: 기초 | C35: 바닥 하부 처리 | D35: 샌드 패드, 아스팔트 샌드, 배수 구배, 기초 레벨 허용오차 | E35: 중 | F35: C | K35: [R32] API 650 Annex B / Annex I | L35: A
A36: 22 | B36: 기초 | C36: 바닥 외면 전기방식 | D36: 탱크 바닥 CP 설치 여부, Liner 설치 | E36: 중 | F36: P / C | K36: [R35] API RP 651 5th (2024) | L36: A
A37: 23 | B37: 기초 | C37: 방유제 (Dike) | D37: 용량 기준(최대 탱크 용량 대비), 방유제 높이·재질, 칸막이 둑 | E37: 중 | F37: C | K37: [R02] 위험물법 시행규칙 별표6 (용량 110%, 높이 0.5~3m) | L37: B
A38: 24 | B38: 기초 | C38: 범위 구분 | D38: 기초 공사가 탱크 업체 범위인지 토목 업체 범위인지 명확화 | E38: 상 | F38: C | K38: 업계 실무 관행 / 발주처 문서 확인 대상 | L38: D
A39: D. 자재 · 구매
A40: 25 | B40: 자재 | C40: 강판 물량 · Nesting | D40: 판 배치(Nesting)에 따른 스크랩율, 판 폭·길이 규격 → 물량 할증 | E40: 상 | F40: P | K40: 업계 실무 관행 / 발주처 문서 확인 대상 | L40: D
A41: 26 | B41: 자재 | C41: 강재 가격 변동 | D41: 철강 가격 변동성, 견적 유효기간, 물가 조정 조항 유무 | E41: 상 | F41: P / 예비비 | K41: 업계 실무 관행 / 발주처 문서 확인 대상 | L41: D
...

Sheet 탱크 타입별 고려사항
A1: 저장탱크 타입별 견적 고려사항
A2: '탱크제작 체크리스트'(공통 항목)에 더해, 탱크 타입에 따라 추가로 확인할 항목. ① 타입 비교표 → ② 타입별 체크리스트
A3: 근거 수준: A=원문·판매처 확인 / B=2차 자료 확인(원문 대조 권장) / C=조항 미확인 / D=실무 관행(공개 출처 없음). 상세는 '참고문헌' 시트
A5: ① 타입 비교표 | J5: 진행 현황
A6: No | B6: 탱크 타입 | C6: 적용 코드 | D6: 압력 · 온도 범위 | E6: 대표 저장물 | F6: 주요 원가 동인 | G6: 주요 리스크 | H6: 출처 | J6: 전체 항목 | K6: =COUNTA(C22:C91) -> 58
A7: 1 | B7: 고정지붕 - Cone Roof | C7: API 650 | D7: 대기압 (소내압은 Annex F) | E7: 중유, 경유, 물, 저증기압 제품 | F7: 지붕 구조(Rafter·Column), 통기설비 | G7: 소내압 운전 시 Annex F 적용 누락 | H7: [R32] API 650, [R37] API 2000 | J7: 완료 | K7: =COUNTIF(G22:G91,"완료") -> 0
A8: 2 | B8: 고정지붕 - 자립 Dome/Umbrella Roof | C8: API 650 | D8: 대기압 ~ 소내압 | E8: 중·소형 일반 제품 | F8: 지붕판 성형(곡면), 지붕-셸 접합부(Compression Ring) | G8: 직경이 크면 지붕판 두께 급증 | H8: [R32] API 650 Annex F | J8: 질의필요 | K8: =COUNTIF(G22:G91,"질의필요") -> 0
A9: 3 | B9: 알루미늄 돔 지붕 | C9: API 650 Annex G | D9: 대기압 | E9: 원유·제품 (신설·개조) | F9: 전문 벤더 Lump-Sum, 셸 상부 지지링 | G9: 돔-셸 하중 전달 설계 책임 경계 | H9: [R32] API 650 Annex G | J9: 해당없음 | K9: =COUNTIF(G22:G91,"해당없음") -> 0
A10: 4 | B10: 외부부상지붕 (EFR) | C10: API 650 Annex C | D10: 대기압 (지붕이 액면에 부상) | E10: 원유, 나프타, 고증기압 제품 | F10: Pontoon/Double Deck, 이중 Seal, Roof Drain, Rolling Ladder, Wind Girder | G10: 셸 진원도 불량 → Seal 간극 불량, 배수 막힘 | H10: [R32] Annex C, 5.9, 7.5 / [R08] 별표16
A11: 5 | B11: 내부부상지붕 (IFR) | C11: API 650 Annex H | D11: 대기압 | E11: 휘발유, 제트유, 화학제품 | F11: 고정지붕 + 내부 Deck(알루미늄 등), Seal, 통기 | G11: Deck 벤더 범위·정전기 접지 | H11: [R32] Annex H, [R37] API 2000, [R08] 별표16
A12: 6 | B12: 고온 · 가열 탱크 | C12: API 650 Annex M | D12: 93°C 초과 ~ 260°C 미만 | E12: 아스팔트, 중질유, 왁스 | F12: Heating Coil, 두꺼운 보온, 허용응력 저하분 두께 증가 | G12: 열팽창에 따른 셸-바닥 접합부 응력, 기초 열영향 | H12: [R32] API 650 Annex M
A13: 7 | B13: 스테인리스 / Duplex 탱크 | C13: API 650 Annex S / Annex X | D13: 대기압 | E13: 화학제품, 식품급, 탈염수 | F13: 고가 자재, 산세·부동태화, 오염 방지 | G13: 탄소강 오염(철분), 시험수 염화물 관리 | H13: [R32] Annex S (S.4.10.1), Annex X, [R31] PCC-2
A14: 8 | B14: 저압 탱크 | C14: API 620 | D14: 대기압 초과 저압 | E14: 저압 저장 제품, 가스 블랭킷 운전 | F14: 곡면 셸·지붕 형상, 앵커 증가, 기압 시험 | G14: 압력 등급 해석 차이 (API 650 Annex F와 경계) | H14: [R33] API 620 12th
A15: 9 | B15: 저온 · 냉동 탱크 | C15: API 620 Annex R (-51°C 이상) / Annex Q (-198°C 이상), API 625 | D15: 저압 · 저온 | E15: LPG, 암모니아, 에틸렌, LNG | F15: 이중각(Single/Double/Full Containment), 9%Ni·SS 내조, 보냉재, 기초 히팅, 콘크리트 외조 | G15: 공기 장기화, Cool-down 시운전, 고압가스법 적용 | H15: [R33] API 620 Annex R/Q, [R34] API 625, [R07] 고압가스법
A16: 10 | B16: 구형 저장탱크 (Sphere) | C16: ASME Sec. VIII / KGS (명칭 미확인) | D16: 고압 (액화가스) | E16: LPG, 프로판, 부탄, 부타디엔 | F16: 고장력강 Petal 공장 성형, 현장 용접 100% RT, 현장 전체 PWHT, 지지 기둥 내화피복, 살수설비 | G16: 중간·완성검사 일정, 수압시험 시 기초 하중 | H16: [R41] ASME VIII (판 미확인), [R11] KGS, [R07] 고압가스법 제16조, [R23] API 2218
A17: 11 | B17: 횡형 압력 저장탱크 (Bullet / Mounded) | C17: ASME Sec. VIII / KGS (명칭 미확인) | D17: 고압 (액화가스) | E17: LPG, 암모니아, 소량 액화가스 | F17: 공장 제작 → 운송 제약(직경·길이), Saddle 기초, Mounded 시 토피·전기방식 | G17: 중량물 운송 경로, Mounded 외면 부식 | H17: [R41] ASME VIII, [R11] KGS, [R07] 고압가스법
A18: 12 | B18: 소형 공장제작 탱크 | C18: API Spec 12F 등 | D18: 대기압 소용량 | E18: 생산 현장 액체, 유틸리티 | F18: 완제품 구매(P 계정), 운송 가능 크기 제한 | G18: 현장 조립 탱크 대비 단가 비교 누락 | H18: [R40] API Spec 12F (2024 개정)
A20: ② 타입별 체크리스트 | D20: 사용법: 입찰 대상이 아닌 타입은 확인상태를 '해당없음'으로 선택하거나, 필터로 해당 타입만 보세요.
A21: No | B21: 타입 | C21: 체크 항목 | D21: 확인 포인트 / 누락 시 리스크 | E21: 영향도 | F21: 견적 반영 위치 | G21: 확인상태 | H21: 견적반영 | I21: 담당 | J21: 비고 | K21: 출처 · 근거 (참고문헌 시트 ID) | L21: 근거 수준
A22: 1. 고정지붕 - Cone Roof
A23: 1 | B23: Cone | C23: 지붕 지지 방식 | D23: 지지형(Rafter + Column) vs 자립형 Cone — 기둥 수·바닥 보강판, 내부 기둥의 부식·검사 영향 | E23: 중 | F23: P / C | K23: [R32] API 650 (지붕 설계 조항 번호 미확인) | L23: C
A24: 2 | B24: Cone | C24: 소내압 운전 여부 | D24: 질소 블랭킷 등 소내압 운전 시 Annex F 적용 → 지붕-셸 접합부, 앵커 추가 | E24: 상 | F24: E / P | K24: [R32] API 650 Annex F | L24: A
A25: 3 | B25: Cone | C25: Frangible Roof 요구 | D25: 비상 시 지붕-셸 접합부 우선 파단 설계 요구 여부 → 접합부 상세·두께 제한 | E25: 중 | F25: E | K25: [R32] API 650 (조항 번호 미확인) | L25: C
A26: 4 | B26: Cone | C26: 통기 · 비상 배기 | D26: 정상 통기 및 화재 시 비상 배기 용량, Breather Valve·화염방지기 수량 | E26: 중 | F26: P | K26: [R37] API Std 2000 8th | L26: A
A27: 2. 고정지붕 - 자립 Dome/Umbrella Roof
A28: 5 | B28: Dome | C28: 지붕판 성형 | D28: 곡면 지붕판 공장 성형(Press) 여부, 운송 가능 크기 | E28: 중 | F28: P / C | K28: 실무 관행 | L28: D
A29: 6 | B29: Dome | C29: 직경 한계 | D29: 자립 지붕은 직경이 커질수록 지붕판 두께가 급격히 증가 → 지지형 또는 알루미늄 돔과 비교 견적 | E29: 상 | F29: E / P | K29: [R32] API 650 (자립 지붕 두께식, 조항 번호 미확인) | L29: C
A30: 7 | B30: Dome | C30: Compression Ring 상세 | D30: 지붕-셸 접합부 압축링 단면, 용접량 | E30: 중 | F30: P / C | K30: [R32] API 650 Annex F / 접합부 조항 미확인 | L30: C
A31: 3. 알루미늄 돔 지붕
A32: 8 | B32: Al Dome | C32: 벤더 범위 | D32: 돔 구조·패널·씰·Skylight·설치까지 Lump-Sum 범위, 크레인·비계 제공 주체 | E32: 상 | F32: P | K32: [R32] API 650 Annex G | L32: A
A33: 9 | B33: Al Dome | C33: 셸 상부 지지링 | D33: 돔 반력(수평 추력) 지지 Ring 설계 책임 — 탱크사 vs 돔 벤더 | E33: 상 | F33: E / C | K33: [R32] API 650 Annex G | L33: A
A34: 10 | B34: Al Dome | C34: 기존 탱크 개조 시 | D34: 기존 EFR에 돔 추가 시 셸 상부 보강, 운전 중 공사 조건 | E34: 중 | F34: C | K34: [R36] API 653 (개조), [R09] KOSHA P-94 | L34: B
A35: 11 | B35: Al Dome | C35: 이종금속 부식 | D35: 알루미늄-탄소강 접촉부 절연 상세 | E35: 하 | F35: P | K35: 실무 관행 | L35: D
A36: 4. 외부부상지붕 (EFR)
A37: 12 | B37: EFR | C37: 지붕 형식 | D37: Pontoon vs Double Deck — 대형·고온 지역은 Double Deck, 강재량 크게 차이 | E37: 상 | F37: P / C | K37: [R32] API 650 Annex C | L37: A
A38: 13 | B38: EFR | C38: 이중 Seal | D38: 1차(Mechanical Shoe/Liquid Mounted) + 2차 Seal 의무, 벤더 견적 확보 | E38: 상 | F38: P | K38: [R08] 대기환경보전법 시행규칙 별표16 (외부부상지붕 이중 밀폐장치), [R32] Annex C | L38: B
A39: 14 | B39: EFR | C39: 셸 진원도 · 내면 평활도 | D39: Seal 밀착을 위한 진원도·용접 덧살 그라인딩 → 시공 MH 증가 | E39: 상 | F39: C | K39: [R32] API 650 7.5 (치수 허용오차) | L39: B
A40: 15 | B40: EFR | C40: Wind Girder · 보강 | D40: 상부 개방 셸의 풍하중 보강링, 보강링 위 통로 겸용 여부 | E40: 중 | F40: P / C | K40: [R32] API 650 5.9 (보강링) | L40: A
A41: 16 | B41: EFR | C41: Roof Drain | D41: Articulated Pipe vs Flexible Hose 배수, 비상 배수, 신뢰성 사양 | E41: 중 | F41: P | K41: [R32] API 650 Annex C (세부 조항 미확인) | L41: C
A42: 17 | B42: EFR | C42: Rolling Ladder · Gauge Pole | D42: 구름 사다리, 게이지 폴, 안티로테이션 장치 | E42: 중 | F42: P | K42: [R32] API 650 Annex C | L42: A
...

Sheet 총괄표
A1: 입찰가 총괄표 (Price Summary)
A2: 각 상세 시트 및 '가정' 시트 요율과 자동 연동
A4: 구분 | B4: 금액 (KRW) | C4: USD 환산 | D4: 구성비 | E4: 산출 근거
A5: 1. 설계 (Engineering) | B5: =E_설계!F14 -> 6087500000 | C5: =B5/가정!$B$5 -> 4411231.9 | D5: =IF($B$17=0,0,B5/$B$17) -> 0.057780597 | E5: E_설계 시트
A6: 2. 기자재 (Procurement) | B6: =P_기자재!N17 -> 36669820000 | C6: =B6/가정!$B$5 -> 26572333 | D6: =IF($B$17=0,0,B6/$B$17) -> 0.34805816 | E6: P_기자재 시트 (CIF/관세 포함)
A7: 3. 시공 (Construction) | B7: =C_시공!L18 -> 27384500000 | C7: =B7/가정!$B$5 -> 19843841 | D7: =IF($B$17=0,0,B7/$B$17) -> 0.25992489 | E7: C_시공 시트
A8: 직접비 소계 (1+2+3) | B8: =SUM(B5:B7) -> 70141820000 | C8: =B8/가정!$B$5 -> 50827406 | D8: =IF($B$17=0,0,B8/$B$17) -> 0.66576365
A9: 4. 현장 간접비 | B9: =간접비!H14 -> 17497721750 | C9: =B9/가정!$B$5 -> 12679509 | D9: =IF($B$17=0,0,B9/$B$17) -> 0.16608276 | E9: 간접비 시트
A10: 직접비 + 간접비 | B10: =B8+B9 -> 87639541750 | C10: =B10/가정!$B$5 -> 63506914 | D10: =IF($B$17=0,0,B10/$B$17) -> 0.83184641
A11: 5. 본사관리비 | B11: =B10*가정!$B$13 -> 4.3819771e+09 | C11: =B11/가정!$B$5 -> 3175345.7 | D11: =IF($B$17=0,0,B11/$B$17) -> 0.04159232 | E11: (직접비+간접비) × 요율
A12: 6. 물가상승 (Escalation) | B12: =B10*가정!$B$14 -> 1752790835 | C12: =B12/가정!$B$5 -> 1270138.3 | D12: =IF($B$17=0,0,B12/$B$17) -> 0.016636928 | E12: (직접비+간접비) × 요율
A13: 7. 예비비 (Contingency) | B13: =(B10+B11+B12)*가정!$B$15 -> 4.6887155e+09 | C13: =B13/가정!$B$5 -> 3397619.9 | D13: =IF($B$17=0,0,B13/$B$17) -> 0.044503783 | E13: (위 합계) × 요율
A14: 총 원가 (Total Cost) | B14: =B10+B11+B12+B13 -> 9.8463025e+10 | C14: =B14/가정!$B$5 -> 71350018 | D14: =IF($B$17=0,0,B14/$B$17) -> 0.93457944
A15: 8. 이윤 (Profit) | B15: =B14*가정!$B$16 -> 6.8924118e+09 | C15: =B15/가정!$B$5 -> 4994501.3 | D15: =IF($B$17=0,0,B15/$B$17) -> 0.065420561 | E15: 총 원가 × 요율
A17: 입찰금액 (VAT 별도) | B17: =B14+B15 -> 1.0535544e+11 | C17: =B17/가정!$B$5 -> 76344520 | D17: =IF($B$17=0,0,B17/$B$17) -> 1 | E17: 제출 금액
A18: 부가가치세 | B18: =B17*가정!$B$17 -> 1.0535544e+10 | C18: =B18/가정!$B$5 -> 7634452
A19: 총 입찰금액 (VAT 포함) | B19: =B17+B18 -> 1.1589098e+11 | C19: =B19/가정!$B$5 -> 83978971
A21: ※ 구성비는 입찰금액(VAT 별도) 대비 비율

Sheet 가정
A1: 견적 기준 및 요율 (Assumptions)
A2: 노란 칸의 값만 바꾸면 전체 견적이 자동 재계산됩니다.
A4: 항목 | B4: 값 | C4: 근거 / 비고
A5: 환율 USD/KRW | B5: 1380 | C5: 샘플값 (출처 없음, D) — 견적 기준일 고시 환율로 교체
A6: 환율 EUR/KRW | B6: 1500 | C6: 샘플값 (출처 없음, D) — 견적 기준일 고시 환율로 교체
A7: 해상운송·보험 (외자 FOB 대비) | B7: 0.04 | C7: 실무 예시값 (D) — 운송사 견적으로 교체
A8: 관세·통관·내륙운송 (외자 FOB 대비) | B8: 0.03 | C8: 실무 예시값 (D) — 품목별 관세율(HS Code) 확인
A9: 국내 기자재 운반비 (FOB 대비) | B9: 0.01 | C9: 실무 예시값 (D)
A10: 산업안전보건관리비 (시공 직접비 대비) | B10: 0.0237 | C10: [R05] 고용노동부고시 제2025-11호 별표1, 50억 이상: 건축 2.37%·토목 2.60%·중건설 3.11%·특수 1.64%. 샘플은 건축공사 적용 — 공사종류 판정 필요 (B)
A11: 건설공사보험 CAR/EAR (직접비 대비) | B11: 0.003 | C11: 보험사 견적 기준 (D)
A12: 보증수수료 (이행·선급·하자, 직접비 대비) | B12: 0.002 | C12: 보증기관 요율 기준 (D). 보증 비율 참고: [R06] 국가계약법 시행령 제50조(계약보증금 10%)
A13: 본사관리비 (Home Office Overhead) | B13: 0.05 | C13: 회사 기준 (D)
A14: 물가상승 (Escalation) | B14: 0.02 | C14: 회사 기준 (D). 계약상 물가조정 조항 유무 확인: [R38] FIDIC Cl.13.7
A15: 예비비 (Contingency) | B15: 0.05 | C15: 회사 리스크 평가 (D). 견적 정확도 범위 참고: [R29] AACE 18R-97 Class 3 -10~-20% / +10~+30%
A16: 이윤 (Profit/Margin) | B16: 0.07 | C16: 경영 판단 (D)
A17: 부가가치세 (VAT) | B17: 0.1 | C17: 부가가치세 세율 10% (부가가치세법)

Sheet E_설계
A1: E. 설계 (Engineering) 견적
A2: 공종별 투입 Man-hour × 시간당 단가 방식
A3: 출처: 이 시트의 수량·단가는 모두 양식 이해용 가상 샘플값입니다(공개 출처 없음, 근거 수준 D). 요율 항목은 '가정' 시트의 근거를 따릅니다.
A4: No | B4: 공종 (Discipline) | C4: 범위 | D4: Man-hour | E4: 단가 (KRW/MH) | F4: 금액 (KRW) | G4: 비고
A5: 1 | B5: 공정 (Process) | C5: Basic + Detail | D5: 6500 | E5: 95000 | F5: =D5*E5 -> 617500000 | G5: PFD, P&ID, H&MB, 공정 데이터시트
A6: 2 | B6: 배관 (Piping) | C6: Detail | D6: 18000 | E6: 85000 | F6: =D6*E6 -> 1530000000 | G6: 3D 모델링, Isometric, 응력해석
A7: 3 | B7: 기계 (Mechanical) | C7: Detail | D7: 7000 | E7: 85000 | F7: =D7*E7 -> 595000000 | G7: 기기 데이터시트, 벤더 도면 검토
A8: 4 | B8: 토목·건축 (Civil/Arch) | C8: Detail | D8: 8500 | E8: 80000 | F8: =D8*E8 -> 680000000 | G8: 기초, 구조물, 건축물
A9: 5 | B9: 구조 (Structural) | C9: Detail | D9: 5000 | E9: 80000 | F9: =D9*E9 -> 400000000 | G9: 파이프랙, 철골구조
A10: 6 | B10: 전기 (Electrical) | C10: Detail | D10: 6000 | E10: 85000 | F10: =D10*E10 -> 510000000 | G10: 단선결선도, 케이블 스케줄
A11: 7 | B11: 계장 (Instrument & Control) | C11: Detail | D11: 7500 | E11: 90000 | F11: =D11*E11 -> 675000000 | G11: Loop 도면, I/O List, DCS 사양
A12: 8 | B12: PM / 문서관리 / 공정관리 | C12: 전 기간 | D12: 9000 | E12: 100000 | F12: =D12*E12 -> 900000000 | G12: PM, 공정·원가·문서 관리
A13: 9 | B13: HAZOP / SIL / 인허가 (외부용역) | C13: Lump Sum | D13: 1 | E13: 180000000 | F13: =D13*E13 -> 180000000 | G13: 수량 1 = Lump Sum
B14: 설계 합계 | D14: =SUM(D5:D12) -> 67500 | F14: =SUM(F5:F13) -> 6087500000 | G14: MH 합계는 Lump Sum 항목 제외

Sheet P_기자재
A1: P. 기자재 구매 (Procurement) 견적
A2: 외자는 FOB 단가 입력 → 환율·운송·관세 자동 반영 / 통화: USD, EUR, KRW
A3: 출처: 이 시트의 수량·단가는 모두 양식 이해용 가상 샘플값입니다(공개 출처 없음, 근거 수준 D). 요율 항목은 '가정' 시트의 근거를 따릅니다.
A4: No | B4: Tag No. | C4: 품명 | D4: 주요 사양 | E4: 수량 | F4: 단위 | G4: 통화 | H4: 외화/원화 단가 | I4: 적용 환율 | J4: 원화 단가 | K4: FOB 금액 (KRW) | L4: 운송·보험 (KRW) | M4: 관세·통관 (KRW) | N4: 합계 (KRW) | O4: 공급처(예정)
A5: 1 | B5: R-101 | C5: 반응기 (Reactor) | D5: SS316L, 3.2m ID × 18m, 25barg | E5: 1 | F5: EA | G5: USD | H5: 2850000 | I5: =IF(G5="USD",가정!$B$5,IF(G5="EUR",가정!$B$6,1)) -> 1380 | J5: =H5*I5 -> 3933000000 | K5: =E5*J5 -> 3933000000 | L5: =IF(G5="KRW",K5*가정!$B$9,K5*가정!$B$7) -> 157320000 | M5: =IF(G5="KRW",0,K5*가정!$B$8) -> 117990000 | N5: =K5+L5+M5 -> 4208310000 | O5: 해외 A사
A6: 2 | B6: T-201 | C6: 증류탑 (Column) | D6: CS+SS clad, 2.8m ID × 42m | E6: 1 | F6: EA | G6: KRW | H6: 3200000000 | I6: =IF(G6="USD",가정!$B$5,IF(G6="EUR",가정!$B$6,1)) -> 1 | J6: =H6*I6 -> 3200000000 | K6: =E6*J6 -> 3200000000 | L6: =IF(G6="KRW",K6*가정!$B$9,K6*가정!$B$7) -> 32000000 | M6: =IF(G6="KRW",0,K6*가정!$B$8) -> 0 | N6: =K6+L6+M6 -> 3232000000 | O6: 국내 B사
A7: 3 | B7: E-301~308 | C7: 열교환기 (S&T) | D7: TEMA AES, CS/SS | E7: 8 | F7: EA | G7: KRW | H7: 185000000 | I7: =IF(G7="USD",가정!$B$5,IF(G7="EUR",가정!$B$6,1)) -> 1 | J7: =H7*I7 -> 185000000 | K7: =E7*J7 -> 1480000000 | L7: =IF(G7="KRW",K7*가정!$B$9,K7*가정!$B$7) -> 14800000 | M7: =IF(G7="KRW",0,K7*가정!$B$8) -> 0 | N7: =K7+L7+M7 -> 1494800000 | O7: 국내 C사
A8: 4 | B8: P-401A/B~ | C8: 원심펌프 | D8: API 610, 전동기 포함 | E8: 12 | F8: EA | G8: EUR | H8: 95000 | I8: =IF(G8="USD",가정!$B$5,IF(G8="EUR",가정!$B$6,1)) -> 1500 | J8: =H8*I8 -> 142500000 | K8: =E8*J8 -> 1710000000 | L8: =IF(G8="KRW",K8*가정!$B$9,K8*가정!$B$7) -> 68400000 | M8: =IF(G8="KRW",0,K8*가정!$B$8) -> 51300000 | N8: =K8+L8+M8 -> 1829700000 | O8: 해외 D사
A9: 5 | B9: K-501 | C9: 압축기 패키지 | D9: 원심식, 2.5MW, 윤활유 시스템 포함 | E9: 1 | F9: SET | G9: USD | H9: 4600000 | I9: =IF(G9="USD",가정!$B$5,IF(G9="EUR",가정!$B$6,1)) -> 1380 | J9: =H9*I9 -> 6348000000 | K9: =E9*J9 -> 6348000000 | L9: =IF(G9="KRW",K9*가정!$B$9,K9*가정!$B$7) -> 253920000 | M9: =IF(G9="KRW",0,K9*가정!$B$8) -> 190440000 | N9: =K9+L9+M9 -> 6792360000 | O9: 해외 E사
A10: 6 | B10: TK-601~604 | C10: 저장탱크 | D10: API 650, 5,000m3 | E10: 4 | F10: EA | G10: KRW | H10: 950000000 | I10: =IF(G10="USD",가정!$B$5,IF(G10="EUR",가정!$B$6,1)) -> 1 | J10: =H10*I10 -> 950000000 | K10: =E10*J10 -> 3800000000 | L10: =IF(G10="KRW",K10*가정!$B$9,K10*가정!$B$7) -> 38000000 | M10: =IF(G10="KRW",0,K10*가정!$B$8) -> 0 | N10: =K10+L10+M10 -> 3838000000 | O10: 국내 F사
A11: 7 | B11: - | C11: 배관 벌크자재 | D11: 파이프·피팅·플랜지 (MTO 기준) | E11: 420 | F11: TON | G11: KRW | H11: 9500000 | I11: =IF(G11="USD",가정!$B$5,IF(G11="EUR",가정!$B$6,1)) -> 1 | J11: =H11*I11 -> 9500000 | K11: =E11*J11 -> 3990000000 | L11: =IF(G11="KRW",K11*가정!$B$9,K11*가정!$B$7) -> 39900000 | M11: =IF(G11="KRW",0,K11*가정!$B$8) -> 0 | N11: =K11+L11+M11 -> 4029900000 | O11: 국내 유통사
A12: 8 | B12: - | C12: 밸브류 | D12: Gate/Globe/Check/Ball | E12: 1 | F12: LOT | G12: KRW | H12: 1850000000 | I12: =IF(G12="USD",가정!$B$5,IF(G12="EUR",가정!$B$6,1)) -> 1 | J12: =H12*I12 -> 1850000000 | K12: =E12*J12 -> 1850000000 | L12: =IF(G12="KRW",K12*가정!$B$9,K12*가정!$B$7) -> 18500000 | M12: =IF(G12="KRW",0,K12*가정!$B$8) -> 0 | N12: =K12+L12+M12 -> 1868500000 | O12: 국내/해외
A13: 9 | B13: - | C13: 전기 벌크 | D13: 변압기·MCC·케이블·트레이 | E13: 1 | F13: LOT | G13: KRW | H13: 2650000000 | I13: =IF(G13="USD",가정!$B$5,IF(G13="EUR",가정!$B$6,1)) -> 1 | J13: =H13*I13 -> 2650000000 | K13: =E13*J13 -> 2650000000 | L13: =IF(G13="KRW",K13*가정!$B$9,K13*가정!$B$7) -> 26500000 | M13: =IF(G13="KRW",0,K13*가정!$B$8) -> 0 | N13: =K13+L13+M13 -> 2676500000 | O13: 국내 G사
A14: 10 | B14: - | C14: 계장품 | D14: 전송기·조절밸브·분석기 | E14: 1 | F14: LOT | G14: USD | H14: 1950000 | I14: =IF(G14="USD",가정!$B$5,IF(G14="EUR",가정!$B$6,1)) -> 1380 | J14: =H14*I14 -> 2691000000 | K14: =E14*J14 -> 2691000000 | L14: =IF(G14="KRW",K14*가정!$B$9,K14*가정!$B$7) -> 107640000 | M14: =IF(G14="KRW",0,K14*가정!$B$8) -> 80730000 | N14: =K14+L14+M14 -> 2879370000 | O14: 해외 H사
A15: 11 | B15: - | C15: DCS / SIS | D15: 제어시스템, 엔지니어링 포함 | E15: 1 | F15: SET | G15: USD | H15: 2300000 | I15: =IF(G15="USD",가정!$B$5,IF(G15="EUR",가정!$B$6,1)) -> 1380 | J15: =H15*I15 -> 3174000000 | K15: =E15*J15 -> 3174000000 | L15: =IF(G15="KRW",K15*가정!$B$9,K15*가정!$B$7) -> 126960000 | M15: =IF(G15="KRW",0,K15*가정!$B$8) -> 95220000 | N15: =K15+L15+M15 -> 3396180000 | O15: 해외 I사
A16: 12 | B16: - | C16: Spare Parts | D16: 시운전 및 2년 운전용 | E16: 1 | F16: LOT | G16: KRW | H16: 420000000 | I16: =IF(G16="USD",가정!$B$5,IF(G16="EUR",가정!$B$6,1)) -> 1 | J16: =H16*I16 -> 420000000 | K16: =E16*J16 -> 420000000 | L16: =IF(G16="KRW",K16*가정!$B$9,K16*가정!$B$7) -> 4200000 | M16: =IF(G16="KRW",0,K16*가정!$B$8) -> 0 | N16: =K16+L16+M16 -> 424200000 | O16: 각 벤더
C17: 기자재 합계 | K17: =SUM(K5:K16) -> 35246000000 | L17: =SUM(L5:L16) -> 888140000 | M17: =SUM(M5:M16) -> 535680000 | N17: =SUM(N5:N16) -> 36669820000

Sheet C_시공
A1: C. 시공 (Construction) 견적
A2: 공종별 물량 × (재료비 + 노무비 + 경비) 단가 — 기자재 본체 구매비는 P에 포함
A3: 출처: 이 시트의 수량·단가는 모두 양식 이해용 가상 샘플값입니다(공개 출처 없음, 근거 수준 D). 요율 항목은 '가정' 시트의 근거를 따릅니다.
A4: No | B4: 공종 | C4: 세부 내역 | D4: 단위 | E4: 수량 | F4: 재료비 단가 | G4: 노무비 단가 | H4: 경비 단가 | I4: 재료비 | J4: 노무비 | K4: 경비 | L4: 합계 (KRW)
A5: 1 | B5: 토목 | C5: 부지정지·터파기 | D5: M3 | E5: 18000 | F5: 0 | G5: 8500 | H5: 6500 | I5: =E5*F5 -> 0 | J5: =E5*G5 -> 153000000 | K5: =E5*H5 -> 117000000 | L5: =I5+J5+K5 -> 270000000
A6: 2 | B6: 토목 | C6: 기초 콘크리트 (철근 포함) | D6: M3 | E6: 6500 | F6: 210000 | G6: 180000 | H6: 45000 | I6: =E6*F6 -> 1365000000 | J6: =E6*G6 -> 1170000000 | K6: =E6*H6 -> 292500000 | L6: =I6+J6+K6 -> 2827500000
A7: 3 | B7: 토목 | C7: 파일 (PHC Φ500) | D7: EA | E7: 1200 | F7: 420000 | G7: 150000 | H7: 90000 | I7: =E7*F7 -> 504000000 | J7: =E7*G7 -> 180000000 | K7: =E7*H7 -> 108000000 | L7: =I7+J7+K7 -> 792000000
A8: 4 | B8: 건축 | C8: 제어실·전기실 건축 | D8: M2 | E8: 1800 | F8: 950000 | G8: 680000 | H8: 120000 | I8: =E8*F8 -> 1710000000 | J8: =E8*G8 -> 1224000000 | K8: =E8*H8 -> 216000000 | L8: =I8+J8+K8 -> 3150000000
A9: 5 | B9: 철골 | C9: 파이프랙·구조물 제작/설치 | D9: TON | E9: 1450 | F9: 1650000 | G9: 950000 | H9: 250000 | I9: =E9*F9 -> 2392500000 | J9: =E9*G9 -> 1377500000 | K9: =E9*H9 -> 362500000 | L9: =I9+J9+K9 -> 4132500000
A10: 6 | B10: 기계 | C10: 기기 설치 (정치·Alignment) | D10: TON | E10: 2600 | F10: 0 | G10: 780000 | H10: 420000 | I10: =E10*F10 -> 0 | J10: =E10*G10 -> 2028000000 | K10: =E10*H10 -> 1092000000 | L10: =I10+J10+K10 -> 3120000000
A11: 7 | B11: 배관 | C11: 배관 제작/설치 (Dia-Inch) | D11: D-I | E11: 98000 | F11: 8000 | G11: 52000 | H11: 9000 | I11: =E11*F11 -> 784000000 | J11: =E11*G11 -> 5096000000 | K11: =E11*H11 -> 882000000 | L11: =I11+J11+K11 -> 6762000000
A12: 8 | B12: 배관 | C12: 수압·기밀시험 | D12: LOT | E12: 1 | F12: 25000000 | G12: 140000000 | H12: 35000000 | I12: =E12*F12 -> 25000000 | J12: =E12*G12 -> 140000000 | K12: =E12*H12 -> 35000000 | L12: =I12+J12+K12 -> 200000000
A13: 9 | B13: 전기 | C13: 케이블 포설·결선 | D13: M | E13: 165000 | F13: 1200 | G13: 6500 | H13: 800 | I13: =E13*F13 -> 198000000 | J13: =E13*G13 -> 1072500000 | K13: =E13*H13 -> 132000000 | L13: =I13+J13+K13 -> 1402500000
A14: 10 | B14: 계장 | C14: 계장품 설치·Loop Test | D14: LOOP | E14: 2400 | F14: 85000 | G14: 420000 | H14: 60000 | I14: =E14*F14 -> 204000000 | J14: =E14*G14 -> 1008000000 | K14: =E14*H14 -> 144000000 | L14: =I14+J14+K14 -> 1356000000
A15: 11 | B15: 도장 | C15: 도장 (표면처리 포함) | D15: M2 | E15: 42000 | F15: 9500 | G15: 14000 | H15: 2500 | I15: =E15*F15 -> 399000000 | J15: =E15*G15 -> 588000000 | K15: =E15*H15 -> 105000000 | L15: =I15+J15+K15 -> 1092000000
A16: 12 | B16: 보온 | C16: 보온·보냉 | D16: M2 | E16: 15000 | F16: 38000 | G16: 42000 | H16: 4000 | I16: =E16*F16 -> 570000000 | J16: =E16*G16 -> 630000000 | K16: =E16*H16 -> 60000000 | L16: =I16+J16+K16 -> 1260000000
A17: 13 | B17: 시운전 | C17: Pre-Comm. / Comm. 지원 | D17: LS | E17: 1 | F17: 150000000 | G17: 650000000 | H17: 220000000 | I17: =E17*F17 -> 150000000 | J17: =E17*G17 -> 650000000 | K17: =E17*H17 -> 220000000 | L17: =I17+J17+K17 -> 1020000000
C18: 시공 직접비 합계 | I18: =SUM(I5:I17) -> 8301500000 | J18: =SUM(J5:J17) -> 15317000000 | K18: =SUM(K5:K17) -> 3766000000 | L18: =SUM(L5:L17) -> 27384500000

Sheet 간접비
A1: 현장 간접비 (Field Indirects & General Expenses)
A2: 인원·기간 기반 항목은 수량×기간×단가, 요율 항목은 '가정' 시트 연동
A3: 출처: 이 시트의 수량·단가는 모두 양식 이해용 가상 샘플값입니다(공개 출처 없음, 근거 수준 D). 요율 항목은 '가정' 시트의 근거를 따릅니다.
A4: No | B4: 항목 | C4: 산출 기준 | D4: 수량 | E4: 단위 | F4: 기간(월) | G4: 단가 (KRW) | H4: 금액 (KRW)
A5: 1 | B5: 현장 관리인원 인건비 | C5: 현장소장·공사·품질·안전·공무 | D5: 35 | E5: 명 | F5: 24 | G5: 9500000 | H5: =D5*F5*G5 -> 7980000000
A6: 2 | B6: 가설 사무실·창고·숙소 | C6: 컨테이너, 임차료, 유지관리 | D6: 1 | E6: 식 | F6: 24 | G6: 85000000 | H6: =D6*F6*G6 -> 2040000000
A7: 3 | B7: 가설 전기·용수·통신 | C7: 인입공사 및 사용료 | D7: 1 | E7: 식 | F7: 24 | G7: 32000000 | H7: =D7*F7*G7 -> 768000000
A8: 4 | B8: 중장비 임차 (크레인 등) | C8: Main 크레인 Mob/Demob 포함 | D8: 1 | E8: 식 | F8: 18 | G8: 210000000 | H8: =D8*F8*G8 -> 3780000000
A9: 5 | B9: 현장 차량·운영 경비 | C9: 차량, 소모품, 복리후생 | D9: 1 | E9: 식 | F9: 24 | G9: 45000000 | H9: =D9*F9*G9 -> 1080000000
A10: 6 | B10: 품질관리 / 비파괴검사 | C10: RT/UT/PT 외주 포함 | D10: 1 | E10: 식 | F10: 1 | G10: 850000000 | H10: =D10*F10*G10 -> 850000000
A11: 7 | B11: 산업안전보건관리비 | C11: 시공 직접비 × 요율 | E11: % | G11: =가정!$B$10 -> 0.0237 | H11: =C_시공!L18*G11 -> 649012650
A12: 8 | B12: 건설공사보험 (CAR/EAR) | C12: E+P+C 직접비 × 요율 | E12: % | G12: =가정!$B$11 -> 0.003 | H12: =(E_설계!F14+P_기자재!N17+C_시공!L18)*G12 -> 210425460
A13: 9 | B13: 보증수수료 (이행·선급·하자) | C13: E+P+C 직접비 × 요율 | E13: % | G13: =가정!$B$12 -> 0.002 | H13: =(E_설계!F14+P_기자재!N17+C_시공!L18)*G13 -> 140283640
B14: 간접비 합계 | H14: =SUM(H5:H13) -> 17497721750

Sheet 조건_제외사항
A1: 견적 조건 · 가정 · 제외사항 (Clarifications & Exclusions)
A2: 입찰 시 견적서와 함께 제출하는 기술·상업 조건 — 프로젝트에 맞게 수정
A4: No | B4: 구분 | C4: 내용 | D4: 출처 · 근거
A5: 1 | B5: 가정 | C5: 견적은 발주처 ITB 및 Basic Design Package(Rev.0) 기준으로 산출함 | D5: 발주처 ITB·SOW 확인 대상 (D)
A6: 2 | B6: 가정 | C6: 부지는 정지 완료 상태로 인도되며, 지장물·오염토 처리는 발주처 부담 | D6: 발주처 ITB·SOW 확인 대상 (D)
A7: 3 | B7: 가정 | C7: 외화 기자재는 견적 기준일 환율 적용, 환율 변동 ±5% 초과 시 협의 | D7: 발주처 ITB·SOW 확인 대상 (D)
A8: 4 | B8: 가정 | C8: 공사 기간은 계약 후 24개월(기계적 준공 기준)이며 주 52시간 근무 기준 | D8: 발주처 ITB·SOW 확인 대상 (D)
A9: 5 | B9: 가정 | C9: 시운전 유틸리티(전력·용수·원료·촉매)는 발주처 공급 | D9: 발주처 ITB·SOW 확인 대상 (D)
A10: 6 | B10: 제외 | C10: 부지 매입, 인허가 수수료 및 각종 부담금 | D10: 발주처 ITB·SOW 확인 대상 (D)
A11: 7 | B11: 제외 | C11: 촉매, 화학약품 및 초기 충전물(First Fill) | D11: 발주처 ITB·SOW 확인 대상 (D)
A12: 8 | B12: 제외 | C12: Plant 외부(Battery Limit 외) 연결 공사 | D12: 발주처 ITB·SOW 확인 대상 (D)
A13: 9 | B13: 제외 | C13: 부가가치세 이외의 세금 및 발주처 귀책 지연에 따른 비용 | D13: 발주처 ITB·SOW 확인 대상 (D)
A14: 10 | B14: 상업조건 | C14: 지급조건: 선급금 10% / 기성(Milestone) 80% / 준공 후 10% | D14: [R38] FIDIC Silver Book Cl.14 (14.2 선급금) — 비율은 예시값(D)
A15: 11 | B15: 상업조건 | C15: 이행보증 10%, 선급금보증 100%, 하자보증 3% (24개월) | D15: [R38] FIDIC Cl.4.2 / 참고 [R06] 국가계약법 시행령 제50조(계약보증 10%), 시행규칙 제72조(일반건축 등 하자보수 3%)
A16: 12 | B16: 상업조건 | C16: 지체상금: 일 0.05%, 계약금액의 10% 한도 | D16: [R06] 국가계약법 시행규칙 제75조(공사 일 0.5/1000 = 0.05%), 공공 상한 30%(시행령 제74조) — 민간은 협의, [R38] Cl.8.8
A17: 13 | B17: 상업조건 | C17: 견적 유효기간: 제출일로부터 90일 | D17: 발주처 ITB 요구 기간 (D)

Sheet 탱크 견적 예시
A1: 탱크 견적작성 예시 (API 650 현장조립 탱크 1기 기준)
A2: 탱크 타입(Cone/Dome/EFR/IFR)을 바꾸면 타입별 항목이 자동 반영됩니다. 물량은 '탱크제작 체크리스트' 하단 산출표와 연동. 모든 단가는 가상 샘플값
A3: 파란 글씨+노란 칸 = 입력 / 검은 글씨 = 계산식 / 초록 글씨 = 다른 시트 연동. 근거 수준 A~D는 '참고문헌' 시트 참조
A5: 1. 견적 기준 | H5: 2. 타입별 계수 (예시)
B6: 항목 | C6: 값 | D6: 출처 · 근거 | E6: 단위 | F6: 근거 수준 | H6: 타입 | I6: 고정지붕 | J6: EFR | K6: IFR | L6: 설치 MH 계수 | M6: Seal 단가 (KRW/m)
B7: 탱크 타입 | C7: Cone Roof | D7: 입찰 범위 ('탱크 타입별 고려사항' 시트 참조) | F7: D | H7: Cone Roof | I7: 1 | J7: 0 | K7: 0 | L7: 1 | M7: 0
B8: 수량 | C8: 4 | D8: P_기자재 TK-601~604 가정과 동일 | E8: 기 | F8: D | H8: Dome Roof | I8: 1 | J8: 0 | K8: 0 | L8: 1.08 | M8: 0
B9: 기초 공사 포함 여부 | C9: N | D9: SOW 범위 확인 ('탱크제작 체크리스트' 기초 범위 구분) | E9: Y/N | F9: D | H9: EFR | I9: 0 | J9: 1 | K9: 0 | L9: 1.18 | M9: 1900000
B10: 내경 D | C10: ='탱크제작 체크리스트'!$E$84 -> 20 | D10: 탱크 산출표 연동 | E10: m | F10: D | H10: IFR | I10: 1 | J10: 0 | K10: 1 | L10: 1.06 | M10: 850000
B11: 셸 높이 H | C11: ='탱크제작 체크리스트'!$E$85 -> 16 | D11: 탱크 산출표 연동 | E11: m | F11: D | H11: ※ 계수·Seal 단가는 예시값(출처 없음, D). 타입별 차이 근거: [R32] API 650 Annex C(EFR)/H(IFR), [R08] 별표16(이중 Seal)
B12: 공칭 용량 | C12: ='탱크제작 체크리스트'!$E$94 -> 5026.5482 | D12: π/4·D²·H | E12: m3 | F12: D
B13: 공칭 용량 (리터) | C13: =C12*1000 -> 5026548.2 | E13: L | F13: D
B14: 탱크안전성능검사 (기초·지반·용접부) | C14: =IF(C13>=1000000,"대상","비대상") -> 대상 | D14: [R01] 위험물법 시행령 제8조 — 옥외 액체위험물탱크 100만L 이상 | F14: B
B15: 완공검사 수행기관 | C15: =IF(C13>=500000,"한국소방산업기술원","시·도") -> 한국소방산업기술원 | D15: [R01] 위험물법 시행령 제22조 — 50만L 이상 옥외탱크저장소 | F15: B
B16: Nesting 스크랩 할증 | C16: ='탱크제작 체크리스트'!$E$91 -> 0.05 | D16: 탱크 산출표 연동 (실무 예시값) | F16: D
B17: EFR Deck·Pontoon 강재 원단위 | C17: 0.055 | D17: 실무 예시값 (출처 없음) — Pontoon/Double Deck 설계 결과로 교체 | E17: t/m2 | F17: D
B18: 설치 중량 (1기) | C18: =('탱크제작 체크리스트'!$E$95+'탱크제작 체크리스트'!$E$96)+'탱크제작 체크리스트'!$E$97*INDEX($I$7:$I$10,MATCH($C$7,$H$7:$H$10,0))+'탱크제작 체크리스트'!$E$99+INDEX($J$7:$J$10,MATCH($C$7,$H$7:$H$10,0))*PI()/4*C10^2*C17 -> 130.79968 | D18: 셸·바닥 + 고정지붕 + 부속 + EFR Deck | E18: ton | F18: D
A20: 3. 견적 상세 (1기)
A21: No | B21: 구분 | C21: 항목 | D21: 산출 기준 | E21: 수량 | F21: 단위 | G21: 단가 (KRW) | H21: 금액 (KRW) | I21: 연계 체크 항목 | J21: 출처 · 근거 | K21: 근거 수준
A22: 1 | B22: 자재 | C22: 셸·바닥 강판 | D22: (셸+바닥 중량) × (1+스크랩) | E22: =('탱크제작 체크리스트'!$E$95+'탱크제작 체크리스트'!$E$96)*(1+$C$16) -> 103.57831 | F22: ton | G22: 1250000 | H22: =E22*G22 -> 1.2947289e+08 | I22: 강판 물량·Nesting | J22: [R32] API 650 5.6 (두께 산정) → 산출표 / 샘플 단가 (출처 없음) — 자사 실적·벤더 견적으로 교체 | K22: B/D
A23: 2 | B23: 자재 | C23: 고정지붕 강판 (Cone·Dome·IFR) | D23: 지붕판 중량 × (1+스크랩) × 고정지붕 여부 | E23: ='탱크제작 체크리스트'!$E$97*(1+$C$16)*INDEX($I$7:$I$10,MATCH($C$7,$H$7:$H$10,0)) -> 15.847481 | F23: ton | G23: 1250000 | H23: =E23*G23 -> 19809352 | I23: 지붕 형식 | J23: 샘플 단가 (출처 없음) — 자사 실적·벤더 견적으로 교체 | K23: D
A24: 3 | B24: 자재 | C24: 부속·구조물 강재 | D24: 계단·플랫폼·보강재·지붕 구조 | E24: ='탱크제작 체크리스트'!$E$99 -> 17.060827 | F24: ton | G24: 1600000 | H24: =E24*G24 -> 27297324 | I24: 부속 설비 | J24: 샘플 단가 (출처 없음) — 자사 실적·벤더 견적으로 교체 | K24: D
A25: 4 | B25: 자재 | C25: EFR Deck · Pontoon | D25: EFR 시: 바닥 면적 × 원단위 | E25: =INDEX($J$7:$J$10,MATCH($C$7,$H$7:$H$10,0))*PI()/4*$C$10^2*$C$17 -> 0 | F25: ton | G25: 1400000 | H25: =E25*G25 -> 0 | I25: EFR 지붕 형식 | J25: [R32] API 650 Annex C / 샘플 단가 (출처 없음) — 자사 실적·벤더 견적으로 교체 | K25: A/D
A26: 5 | B26: 자재 | C26: IFR 알루미늄 Deck (벤더) | D26: IFR 시: 바닥 면적 | E26: =INDEX($K$7:$K$10,MATCH($C$7,$H$7:$H$10,0))*PI()/4*$C$10^2 -> 0 | F26: m2 | G26: 280000 | H26: =E26*G26 -> 0 | I26: IFR Deck 형식 | J26: [R32] API 650 Annex H / 샘플 단가 (출처 없음) — 자사 실적·벤더 견적으로 교체 | K26: A/D
A27: 6 | B27: 자재 | C27: 부상지붕 Seal | D27: EFR·IFR 시: 원주 πD (EFR은 이중 Seal 단가) | E27: =(INDEX($J$7:$J$10,MATCH($C$7,$H$7:$H$10,0))+INDEX($K$7:$K$10,MATCH($C$7,$H$7:$H$10,0)))*PI()*$C$10 -> 0 | F27: m | G27: =INDEX($M$7:$M$10,MATCH($C$7,$H$7:$H$10,0)) -> 0 | H27: =E27*G27 -> 0 | I27: 이중 Seal / Seal 형식 | J27: [R08] 대기환경보전법 시행규칙 별표16 / 샘플 단가 (출처 없음) — 자사 실적·벤더 견적으로 교체 | K27: B/D
A28: 7 | B28: 자재 | C28: Roof Drain · Rolling Ladder | D28: EFR 시 1식 | E28: =INDEX($J$7:$J$10,MATCH($C$7,$H$7:$H$10,0)) -> 0 | F28: 식 | G28: 160000000 | H28: =E28*G28 -> 0 | I28: Roof Drain / Rolling Ladder | J28: [R32] API 650 Annex C / 샘플 단가 (출처 없음) — 자사 실적·벤더 견적으로 교체 | K28: A/D
A29: 8 | B29: 자재 | C29: 노즐·맨홀·부속품 | D29: 노즐 단조품, 게이지, 통기·화염방지기 | E29: 1 | F29: 식 | G29: 85000000 | H29: =E29*G29 -> 85000000 | I29: 노즐·맨홀 / 통기 | J29: [R37] API 2000 (통기 용량) / 샘플 단가 (출처 없음) — 자사 실적·벤더 견적으로 교체 | K29: A/D
A30: 9 | B30: 자재 | C30: 용접 소모품 | D30: 설치 중량 기준 | E30: =$C$18 -> 130.79968 | F30: ton | G30: 110000 | H30: =E30*G30 -> 14387964 | I30: 소모품 | J30: 샘플 단가 (출처 없음) — 자사 실적·벤더 견적으로 교체 | K30: D
A31: 10 | B31: 시공 | C31: 제작·설치 노무 | D31: 설치 중량 × 30 MH/ton × 타입 계수 | E31: =$C$18*30*INDEX($L$7:$L$10,MATCH($C$7,$H$7:$H$10,0)) -> 3923.9903 | F31: MH | G31: 48000 | H31: =E31*G31 -> 1.8835153e+08 | I31: 조립 공법 / 용접 생산성 | J31: MH 원단위·노임 모두 예시값 — 샘플 단가 (출처 없음) — 자사 실적·벤더 견적으로 교체 | K31: D
A32: 11 | B32: 시공 | C32: Jack-up 장비 · 크레인 | D32: 동원 기간 | E32: 3 | F32: 월 | G32: 95000000 | H32: =E32*G32 -> 285000000 | I32: 크레인·장비 | J32: 샘플 단가 (출처 없음) — 자사 실적·벤더 견적으로 교체 | K32: D
A33: 12 | B33: 시공 | C33: 비계 · 작업대 | D33: 셸 내·외부 | E33: 1 | F33: 식 | G33: 60000000 | H33: =E33*G33 -> 60000000 | I33: 비계·작업대 | J33: 샘플 단가 (출처 없음) — 자사 실적·벤더 견적으로 교체 | K33: D
A34: 13 | B34: 시공 | C34: 치수 교정 · 그라인딩 | D34: EFR은 진원도·내면 평활도 관리 강화 | E34: =1+INDEX($J$7:$J$10,MATCH($C$7,$H$7:$H$10,0)) -> 1 | F34: 식 | G34: 15000000 | H34: =E34*G34 -> 15000000 | I34: 치수 관리 / 셸 진원도 | J34: [R32] API 650 7.5 / 샘플 단가 (출처 없음) — 자사 실적·벤더 견적으로 교체 | K34: B/D
A35: 14 | B35: 검사 | C35: 셸 RT (Spot) | D35: 용접 길이·두께별 매수 (예시 120매) | E35: 120 | F35: 매 | G35: 85000 | H35: =E35*G35 -> 10200000 | I35: 셸 용접부 RT | J35: [R32] API 650 8.1 / 샘플 단가 (출처 없음) — 자사 실적·벤더 견적으로 교체 | K35: B/D
A36: 15 | B36: 검사 | C36: 바닥 진공시험 | D36: 바닥 면적 × 0.75 m/m2 (용접 길이 원단위 예시) | E36: =PI()/4*$C$10^2*0.75 -> 235.61945 | F36: m | G36: 9000 | H36: =E36*G36 -> 2120575 | I36: 바닥 진공시험 | J36: [R32] API 650 (조항 미확인) / 샘플 단가 (출처 없음) — 자사 실적·벤더 견적으로 교체 | K36: C/D
A37: 16 | B37: 시험 | C37: 충수 시험수 공급 | D37: 공칭 용량 | E37: =$C$12 -> 5026.5482 | F37: m3 | G37: 1800 | H37: =E37*G37 -> 9047786.8 | I37: 수압(충수) 시험수 | J37: [R32] API 650 7.3.6 / 용수 단가 샘플 단가 (출처 없음) — 자사 실적·벤더 견적으로 교체 | K37: B/D
A38: 17 | B38: 시험 | C38: 시험수 배수 처리 | D38: 공칭 용량 | E38: =$C$12 -> 5026.5482 | F38: m3 | G38: 1200 | H38: =E38*G38 -> 6031857.9 | I38: 수압(충수) 시험수 | J38: 샘플 단가 (출처 없음) — 자사 실적·벤더 견적으로 교체 | K38: D
A39: 18 | B39: 시험 | C39: 부상 시험 · 침하 측정 | D39: 충수 단계별 측정 (EFR·IFR은 부상 시험 추가) | E39: =1+INDEX($J$7:$J$10,MATCH($C$7,$H$7:$H$10,0))+INDEX($K$7:$K$10,MATCH($C$7,$H$7:$H$10,0)) -> 1 | F39: 식 | G39: 8000000 | H39: =E39*G39 -> 8000000 | I39: 충수 기간·침하 / 부상 시험 | J39: [R32] API 650 7.3.6, Annex B / 샘플 단가 (출처 없음) — 자사 실적·벤더 견적으로 교체 | K39: B/D
A40: 19 | B40: 인허가 | C40: 탱크안전성능검사·완공검사 대응 | D40: 검사 대상이면 1식 (수수료 금액은 기술원 기준 확인) | E40: =IF($C$14="대상",1,0) -> 1 | F40: 식 | G40: 15000000 | H40: =E40*G40 -> 15000000 | I40: 탱크안전성능검사 / 완공검사 | J40: [R01] 위험물법 제8·9조, 시행령 제8·22조 / 금액은 예시 | K40: B/D
A41: 20 | B41: 도장 | C41: 외부 도장 (셸 + 지붕) | D41: πDH + 바닥면적×1.02 (지붕) | E41: =PI()*$C$10*$C$11+PI()/4*$C$10^2*1.02 -> 1325.7521 | F41: m2 | G41: 28000 | H41: =E41*G41 -> 37121059 | I41: 외부 도장 | J41: [R28] ISO 8501-1 (표면처리 등급) / 샘플 단가 (출처 없음) — 자사 실적·벤더 견적으로 교체 | K41: A/D
A42: 21 | B42: 도장 | C42: 내부 코팅 (바닥 + 셸 하부 1m) | D42: 바닥면적 + πD × 1m | E42: =PI()/4*$C$10^2+PI()*$C$10*1 -> 376.99112 | F42: m2 | G42: 45000 | H42: =E42*G42 -> 16964600 | I42: 내부 라이닝·코팅 | J42: 샘플 단가 (출처 없음) — 자사 실적·벤더 견적으로 교체 | K42: D
...

Sheet 배관 견적 예시
A1: 배관 공사 견적작성 예시 (석유화학 플랜트)
A2: 라인 그룹별 재질·두께·현장조건·서비스 등급을 고르면 공수·검사·PWHT 물량이 계산됩니다. 보정계수는 '석유화학·배관 체크리스트' 하단 표와 연동. 모든 단가는 가상 샘플값
A3: 파란 글씨+노란 칸 = 입력 / 검은 글씨 = 계산식 / 초록 글씨 = 다른 시트 연동. 근거 수준 A~D는 '참고문헌' 시트 참조
A5: 1. 계수표
B6: 재질 | C6: 계수 | E6: 두께 | F6: 계수 | H6: 현장 조건 | I6: 계수 | K6: 서비스 등급 | L6: RT/UT 비율 | M6: 출처
B7: 탄소강 (CS) | C7: ='석유화학·배관 체크리스트'!$E$72 -> 1 | E7: Sch.40 이하 | F7: 1 | H7: 일반 | I7: 1 | K7: Normal | L7: 0.05 | M7: [R12] B31.3 341.4.1 (5% 랜덤)
B8: 저온탄소강 (LTCS) | C8: ='석유화학·배관 체크리스트'!$E$73 -> 1.15 | E8: Sch.80 / XS | F8: ='석유화학·배관 체크리스트'!$E$77 -> 1.3 | H8: 파이프랙 상단·고소 | I8: ='석유화학·배관 체크리스트'!$E$79 -> 1.15 | K8: Category D | L8: 0 | M8: [R12] B31.3 341.4.2 (육안검사)
B9: 스테인리스 (SS304/316) | C9: ='석유화학·배관 체크리스트'!$E$74 -> 1.6 | E9: Sch.160 / XXS (후육관) | F9: ='석유화학·배관 체크리스트'!$E$78 -> 1.8 | H9: 기존 설비 밀집 구역 | I9: ='석유화학·배관 체크리스트'!$E$80 -> 1.25 | K9: Severe cyclic | L9: 1 | M9: [R12] B31.3 맞대기 100% 체적검사 (조항 번호 미확인)
B10: 합금강 (Cr-Mo) | C10: ='석유화학·배관 체크리스트'!$E$75 -> 2 | H10: 운전 중 공장 (작업허가) | I10: ='석유화학·배관 체크리스트'!$E$81 -> 1.3
B11: Duplex / 고합금 | C11: ='석유화학·배관 체크리스트'!$E$76 -> 2.5
B12: ※ 재질·두께·현장 계수는 예시값(출처 없음, D). RT 비율은 코드 최소값이며 발주처 사양이 상향 요구할 수 있음(라인별 '발주처 RT 비율'에 입력)
B13: 기준 MH / Dia-Inch | C13: ='석유화학·배관 체크리스트'!$E$84 -> 0.55 | D13: MH/DI | E13: 배관 체크리스트 계산 예시와 연동 (예시값, D)
B14: 노임 단가 | C14: 48000 | D14: KRW/MH | E14: 샘플 단가 (출처 없음) — 자사 실적·벤더 견적으로 교체
A16: 2. 라인 그룹별 물량
A17: No | B17: 라인 그룹 | C17: 재질 | D17: 두께 | E17: 현장 조건 | F17: 서비스 등급 | G17: Dia-Inch | H17: 맞대기 용접 수 | I17: PWHT | J17: 자재 단가 (KRW/DI) | K17: 재질계수 | L17: 두께계수 | M17: 현장계수 | N17: 공수 (MH) | O17: 노무비 (KRW) | P17: 자재비 (KRW) | Q17: 발주처 RT 비율 | R17: 적용 RT 비율 | S17: RT 대상 조인트
A18: 1 | B18: 공정 배관 (일반) | C18: 탄소강 (CS) | D18: Sch.40 이하 | E18: 파이프랙 상단·고소 | F18: Normal | G18: 14000 | H18: 3800 | I18: N | J18: 55000 | K18: =INDEX($C$7:$C$11,MATCH(C18,$B$7:$B$11,0)) -> 1 | L18: =INDEX($F$7:$F$9,MATCH(D18,$E$7:$E$9,0)) -> 1 | M18: =INDEX($I$7:$I$10,MATCH(E18,$H$7:$H$10,0)) -> 1.15 | N18: =G18*$C$13*K18*L18*M18 -> 8855 | O18: =N18*$C$14 -> 425040000 | P18: =G18*J18 -> 770000000 | R18: =IF(Q18="",INDEX($L$7:$L$9,MATCH(F18,$K$7:$K$9,0)),MAX(Q18,INDEX($L$7:$L$9,MATCH(F18,$K$7:$K$9,0)))) -> 0.05 | S18: =ROUNDUP(H18*R18,0) -> 190
A19: 2 | B19: 저온 배관 | C19: 저온탄소강 (LTCS) | D19: Sch.40 이하 | E19: 일반 | F19: Normal | G19: 3000 | H19: 850 | I19: N | J19: 80000 | K19: =INDEX($C$7:$C$11,MATCH(C19,$B$7:$B$11,0)) -> 1.15 | L19: =INDEX($F$7:$F$9,MATCH(D19,$E$7:$E$9,0)) -> 1 | M19: =INDEX($I$7:$I$10,MATCH(E19,$H$7:$H$10,0)) -> 1 | N19: =G19*$C$13*K19*L19*M19 -> 1897.5 | O19: =N19*$C$14 -> 91080000 | P19: =G19*J19 -> 240000000 | R19: =IF(Q19="",INDEX($L$7:$L$9,MATCH(F19,$K$7:$K$9,0)),MAX(Q19,INDEX($L$7:$L$9,MATCH(F19,$K$7:$K$9,0)))) -> 0.05 | S19: =ROUNDUP(H19*R19,0) -> 43
A20: 3 | B20: SS 배관 (부식 서비스) | C20: 스테인리스 (SS304/316) | D20: Sch.40 이하 | E20: 기존 설비 밀집 구역 | F20: Normal | G20: 2500 | H20: 780 | I20: N | J20: 150000 | K20: =INDEX($C$7:$C$11,MATCH(C20,$B$7:$B$11,0)) -> 1.6 | L20: =INDEX($F$7:$F$9,MATCH(D20,$E$7:$E$9,0)) -> 1 | M20: =INDEX($I$7:$I$10,MATCH(E20,$H$7:$H$10,0)) -> 1.25 | N20: =G20*$C$13*K20*L20*M20 -> 2750 | O20: =N20*$C$14 -> 132000000 | P20: =G20*J20 -> 375000000 | Q20: 0.1 | R20: =IF(Q20="",INDEX($L$7:$L$9,MATCH(F20,$K$7:$K$9,0)),MAX(Q20,INDEX($L$7:$L$9,MATCH(F20,$K$7:$K$9,0)))) -> 0.1 | S20: =ROUNDUP(H20*R20,0) -> 78
A21: 4 | B21: 고온 배관 | C21: 합금강 (Cr-Mo) | D21: Sch.80 / XS | E21: 일반 | F21: Normal | G21: 1500 | H21: 380 | I21: Y | J21: 210000 | K21: =INDEX($C$7:$C$11,MATCH(C21,$B$7:$B$11,0)) -> 2 | L21: =INDEX($F$7:$F$9,MATCH(D21,$E$7:$E$9,0)) -> 1.3 | M21: =INDEX($I$7:$I$10,MATCH(E21,$H$7:$H$10,0)) -> 1 | N21: =G21*$C$13*K21*L21*M21 -> 2145 | O21: =N21*$C$14 -> 102960000 | P21: =G21*J21 -> 315000000 | R21: =IF(Q21="",INDEX($L$7:$L$9,MATCH(F21,$K$7:$K$9,0)),MAX(Q21,INDEX($L$7:$L$9,MATCH(F21,$K$7:$K$9,0)))) -> 0.05 | S21: =ROUNDUP(H21*R21,0) -> 19
A22: 5 | B22: 압축기 토출 배관 | C22: 탄소강 (CS) | D22: Sch.160 / XXS (후육관) | E22: 일반 | F22: Severe cyclic | G22: 600 | H22: 150 | I22: N | J22: 95000 | K22: =INDEX($C$7:$C$11,MATCH(C22,$B$7:$B$11,0)) -> 1 | L22: =INDEX($F$7:$F$9,MATCH(D22,$E$7:$E$9,0)) -> 1.8 | M22: =INDEX($I$7:$I$10,MATCH(E22,$H$7:$H$10,0)) -> 1 | N22: =G22*$C$13*K22*L22*M22 -> 594 | O22: =N22*$C$14 -> 28512000 | P22: =G22*J22 -> 57000000 | R22: =IF(Q22="",INDEX($L$7:$L$9,MATCH(F22,$K$7:$K$9,0)),MAX(Q22,INDEX($L$7:$L$9,MATCH(F22,$K$7:$K$9,0)))) -> 1 | S22: =ROUNDUP(H22*R22,0) -> 150
A23: 6 | B23: Tie-in (운전 중 연결) | C23: 탄소강 (CS) | D23: Sch.80 / XS | E23: 운전 중 공장 (작업허가) | F23: Normal | G23: 400 | H23: 60 | I23: N | J23: 70000 | K23: =INDEX($C$7:$C$11,MATCH(C23,$B$7:$B$11,0)) -> 1 | L23: =INDEX($F$7:$F$9,MATCH(D23,$E$7:$E$9,0)) -> 1.3 | M23: =INDEX($I$7:$I$10,MATCH(E23,$H$7:$H$10,0)) -> 1.3 | N23: =G23*$C$13*K23*L23*M23 -> 371.8 | O23: =N23*$C$14 -> 17846400 | P23: =G23*J23 -> 28000000 | R23: =IF(Q23="",INDEX($L$7:$L$9,MATCH(F23,$K$7:$K$9,0)),MAX(Q23,INDEX($L$7:$L$9,MATCH(F23,$K$7:$K$9,0)))) -> 0.05 | S23: =ROUNDUP(H23*R23,0) -> 3
B24: 합계 | G24: =SUM(G18:G23) -> 22000 | H24: =SUM(H18:H23) -> 6020 | N24: =SUM(N18:N23) -> 16613.3 | O24: =SUM(O18:O23) -> 797438400 | P24: =SUM(P18:P23) -> 1785000000 | S24: =SUM(S18:S23) -> 483
A26: 3. 배관 공사 견적 집계
A27: No | B27: 항목 | C27: 산출 기준 | F27: 수량 | G27: 단위 | H27: 단가 (KRW) | I27: 금액 (KRW) | J27: 연계 체크 항목 | L27: 출처 · 근거 | O27: 근거 수준
A28: 1 | B28: 배관 제작·설치 노무비 | C28: 라인 그룹 표 노무비 합계 | F28: =O24 -> 797438400 | G28: 식 | I28: =F28 -> 797438400 | J28: Dia-Inch 단가 보정 | L28: 공수 예시값 (참고서 [R30] Page, 수치 미인용) | O28: D
A29: 2 | B29: 배관 자재비 | C29: 라인 그룹 표 자재비 합계 | F29: =P24 -> 1785000000 | G29: 식 | I29: =F29 -> 1785000000 | J29: Piping Class / Material Spec | L29: 샘플 단가 (출처 없음) — 자사 실적·벤더 견적으로 교체 | O29: D
A30: 3 | B30: MTO 물량 할증 | C30: 자재비 × 10% | F30: =P24 -> 1785000000 | G30: KRW | H30: 0.1 | I30: =F30*H30 -> 178500000 | J30: MTO 정확도·할증률 | L30: 실무 예시값 (FEED 수준 연동: [R29] AACE 18R-97) | O30: D
A31: 4 | B31: RT / UT 검사 | C31: RT 대상 조인트 수 | F31: =S24 -> 483 | G31: 조인트 | H31: 85000 | I31: =F31*H31 -> 41055000 | J31: 비파괴검사 (NDE) | L31: [R12] ASME B31.3 341.4.1 / M341.4 / Severe cyclic 100% — 단가 샘플 단가 (출처 없음) — 자사 실적·벤더 견적으로 교체 | O31: B/D
A32: 5 | B32: PWHT | C32: PWHT=Y 그룹 용접 수 | F32: =SUMIF(I18:I23,"Y",H18:H23) -> 380 | G32: 조인트 | H32: 180000 | I32: =F32*H32 -> 68400000 | J32: 예열 · PWHT | L32: [R12] ASME B31.3 Table 331.1.1 — 단가 샘플 단가 (출처 없음) — 자사 실적·벤더 견적으로 교체 | O32: B/D
A33: 6 | B33: 경도시험 (PWHT 조인트) | C33: PWHT 조인트 수 | F33: =SUMIF(I18:I23,"Y",H18:H23) -> 380 | G33: 조인트 | H33: 15000 | I33: =F33*H33 -> 5700000 | J33: 경도시험 · PMI | L33: B31.3 331.1.7 삭제(2014판) → 프로젝트 사양 / [R13][R14] NACE | O33: B/D
A34: 7 | B34: PMI (SS·합금 조인트) | C34: SS·Cr-Mo·Duplex 그룹 용접 수 | F34: =SUMIF($C$18:$C$23,"스테인리스 (SS304/316)",H18:H23)+SUMIF($C$18:$C$23,"합금강 (Cr-Mo)",H18:H23)+SUMIF($C$18:$C$23,"Duplex / 고합금",H18:H23) -> 1160 | G34: 조인트 | H34: 25000 | I34: =F34*H34 -> 29000000 | J34: 경도시험 · PMI | L34: 발주처 사양 (공개 출처 없음) — 단가 샘플 단가 (출처 없음) — 자사 실적·벤더 견적으로 교체 | O34: D
A35: 8 | B35: 수압시험 (Test Package) | C35: Test Package 수 | F35: 85 | G35: Pkg | H35: 2500000 | I35: =F35*H35 -> 212500000 | J35: 수압·기압 시험 | L35: [R12] ASME B31.3 345.4.2 (1.5×P×St/S) — 단가 샘플 단가 (출처 없음) — 자사 실적·벤더 견적으로 교체 | O35: B/D
A36: 9 | B36: SS 배관 저염소 시험수 | C36: 시험수량 | F36: 600 | G36: m3 | H36: 3000 | I36: =F36*H36 -> 1800000 | J36: 시험수 수질 · 처리 | L36: [R31] ASME PCC-2 (염화물 50 ppm 미만) — 단가 샘플 단가 (출처 없음) — 자사 실적·벤더 견적으로 교체 | O36: B/D
A37: 10 | B37: 비계 | C37: 노무비 × 15% | F37: =O24 -> 797438400 | G37: KRW | H37: 0.15 | I37: =F37*H37 -> 119615760 | J37: 비계 (Scaffolding) | L37: 실무 예시값 (D) | O37: D
A38: 11 | B38: 배관 서포트 (일반·특수) | C38: 서포트 중량 | F38: 180 | G38: ton | H38: 3200000 | I38: =F38*H38 -> 576000000 | J38: 특수 서포트 | L38: 샘플 단가 (출처 없음) — 자사 실적·벤더 견적으로 교체 | O38: D
A39: 12 | B39: Flushing · Blowing · 화학세정 | C39: 1식 | F39: 1 | G39: 식 | H39: 120000000 | I39: =F39*H39 -> 120000000 | J39: Flushing / 화학 세정 | L39: 샘플 단가 (출처 없음) — 자사 실적·벤더 견적으로 교체 | O39: D
A40: 13 | B40: Hot Tap (운전 중 Tie-in) | C40: Hot Tap 개소 | F40: 6 | G40: 개소 | H40: 18000000 | I40: =F40*H40 -> 108000000 | J40: Tie-in 방식 | L40: [R22] API RP 2201 — 단가 샘플 단가 (출처 없음) — 자사 실적·벤더 견적으로 교체 | O40: A/D
B41: 배관 공사 합계 (직접비) | I41: =SUM(I28:I40) -> 4043009160 | J41: ※ 'C_시공' 시트의 배관 항목(Dia-Inch 단가 방식)과 비교·검증용 상세 예시입니다.
B42: Dia-Inch당 평균 단가 (검토용) | I42: =IF(G24=0,0,I41/G24) -> 183773.14

Sheet 참고문헌
A1: 참고문헌 · 출처 목록
A2: 2026-10-16 기준 확인. 유료 규격(API·ASME)은 원문을 열람하지 못한 경우가 많아 2차 자료로 조항을 확인했습니다 — 입찰 제출 전 최신 원문과 대조하세요.
A4: 근거 수준
A5: A | B5: 발행처·판매처·법령 원문에서 판/내용 확인
A6: B | B6: 해설·포럼·기사 등 2차 자료로 확인 — 입찰 전 원문 대조 권장
A7: C | B7: 조항 번호·명칭 미확인 — 반드시 원문 확인 필요
A8: D | B8: 업계 실무 관행 / 발주처 문서 확인 대상 — 특정 공개 출처 없음
A10: ID | B10: 구분 | C10: 문서명 · 조항 · 내용 | D10: 판 / 상태 (2026-10 기준) | E10: 확인 수준 | F10: URL (확인한 자료) | G10: 비고
A11: R01 | B11: 국내 법령 | C11: 위험물안전관리법 제8조(탱크안전성능검사)·제9조(완공검사), 시행령 제8조(검사 대상: 기초·지반/용접부 100만L 이상 옥외탱크, 충수·수압 전 액체위험물탱크)·제9조·제22조(한국소방산업기술원 위탁) | D11: 법률 제20231호, 2025.8.7 시행 | E11: B | F11: https://www.taxcanvas.kr/core/law/0097072025080535696/history/2025-08-07 | G11: 법령 미러로 확인. law.go.kr 원문 대조 권장. 별표4 본문 미확인
A12: R02 | B12: 국내 법령 | C12: 위험물안전관리법 시행규칙 별표6 옥외탱크저장소 기준(제30조 관련): 방유제 용량 110%(최대 탱크 기준), 높이 0.5~3m, 보유공지 | D12: 별표6 2021.7.13 개정 | E12: B | F12: https://www.kfsi.or.kr/contents/webzine/202003/sub02-01.html | G12: 2차 자료(소방안전 웹진). 호·목 번호 미확인
A13: R03 | B13: 국내 법령 | C13: 화학물질관리법 제23조(화학사고예방관리계획서), 제24조(취급시설 배치·설치 및 관리 기준) | D13: 법률 제20231호; 2021.4.1 장외영향평가·위해관리계획서 → 화학사고예방관리계획서 통합 | E13: B | F13: https://elaw.klri.re.kr/kor_service/lawViewTitle.do?hseq=64986 | G13: 통합 경위: https://www.shinkim.com/kor/media/newsletter/1475 . 2024~25 개정의 취급시설 기준 변경 여부 미확인
A14: R04 | B14: 국내 법령 | C14: 산업안전보건법 제44조(공정안전보고서), 시행령 제43조(PSM 제출 대상: 원유정제, 석유화학계 기초화학물질 등 7개 업종), 시행규칙 제51조(착공 30일 전 제출) | D14: 시행규칙 고용노동부령 제477호(2026.8.1 시행) | E14: B | F14: https://www.esafetykorea.or.kr | G14: 안전보건 정보 사이트 게시 법령 PDF로 확인
A15: R05 | B15: 국내 고시 | C15: 고용노동부고시 제2025-11호 「건설업 산업안전보건관리비 계상 및 사용기준」 별표1 요율(50억 이상: 건축 2.37%, 토목 2.60%, 중건설 3.11%, 특수건설 1.64%) | D15: 2025.1.1 이후 계약 공사부터 적용 | E15: B | F15: https://www.koscaj.com/news/articleView.html?idxno=311178 | G15: 공사종류는 고시 기준에 따라 판정 필요
A16: R06 | B16: 국내 법령 | C16: 국가계약법 시행규칙 제75조(지체상금률: 공사 일 0.5/1000), 시행령 제74조제3항(지체상금 상한 30%), 시행령 제50조(계약보증금: 공사 10%, 2026.5 개정 15%→10%), 시행령 제62조·시행규칙 제72조(하자보수보증금 2~10%, 일반건축 등 3%) | D16: 2026.5 시행령 개정 반영 | E16: B | F16: https://www.lawtalk.co.kr/posts/165966 | G16: 계약보증금 개정: https://www.newspim.com/news/view/20260506000359 . 공공계약 기준이며 민간 EPC는 계약서 우선
A17: R07 | B17: 국내 법령 | C17: 고압가스 안전관리법 제16조(중간검사·완성검사), 제16조의2(정기·수시검사) | D17: 법률 제21438호(2026.3.10 타법개정) | E17: B | F17: https://www.nepla.ai/law/고압가스안전관리법
A18: R08 | B18: 국내 법령 | C18: 대기환경보전법 시행규칙 별표16 VOC 배출 억제·방지시설 기준 1호 나목(저장시설): 내부부상지붕 Seal 형식, 외부부상지붕 이중 밀폐장치 | D18: 2020년경 자료 기준, 최신 개정 미확인 | E18: B | F18: https://tour.gunsan.go.kr/_cms/board/eFileDownload/111/941653/72ce799e30239c962e6616e382d24dea | G18: 지자체 첨부 문서로 확인
A19: R09 | B19: 국내 지침 | C19: KOSHA GUIDE P-94-2019 안전작업허가지침 | D19: 2019판 (이후 개정 여부 미확인) | E19: B | F19: https://hseworld.co.kr/36 | G19: kosha.or.kr에서 최신판 확인 필요
A20: R10 | B20: 국내 기준 | C20: KDS 41 17 00 건축물 내진설계기준 19.6절(탱크 및 저장용기) | D20: KDS 41 17 00:2022 | E20: B | F20: https://www.kim2kie.com/res/html/0_formula/00%20Dynamics/KDS%2041/KDS%2041%2017%2000.pdf | G20: 2022 이후 개정 미확인. 소방청 위험물 세부기준 내진 조항 미확인
A21: R11 | B21: 국내 기준 | C21: KGS Code: AC111(저장탱크·압력용기 제조 관련), FP111/FP112(고압가스 특정·일반제조 시설) | D21: 정식 명칭·최신판 미확인 | E21: C | F21: https://www.kgs.or.kr | G21: 명칭 미확인. KGS 원문 확인 필요
A22: R12 | B22: 국제 코드 | C22: ASME B31.3 Process Piping: 341.4.1(Normal 5% 랜덤 RT/UT), 341.4.2(Category D 육안), Severe cyclic 맞대기 100% 체적검사(조항 번호 미확인), M341.4(Category M), 345.4.2(수압 1.5×P×St/S), 345.5.4(공압 1.1×), Table 331.1.1(PWHT), 323.2.2/323.3(저온 충격시험). ※331.1.7 경도 요건은 2014판에서 삭제 | D22: 2024 Edition (2024.12 발행) | E22: B | F22: https://epcland.com/asme-b31-3-pressure-leak-test-2/ | G22: 판은 API 570 시험대상 규격표로 확인(A). 조항은 2차 자료. 원문 대조 권장
A23: R13 | B23: 국제 코드 | C23: NACE MR0175 / ISO 15156 (석유·가스 생산 Sour 서비스 재질) | D23: MR0175-2021 / ISO 15156:2020 | E23: A | F23: https://webstore.ansi.org/standards/nace/ansinacemr01752021iso151562020
A24: R14 | B24: 국제 코드 | C24: NACE MR0103 / ISO 17945 (정유·석유화학 Sour 서비스 재질) | D24: MR0103-2015 / ISO 17945:2015 (R2023) | E24: A | F24: https://webstore.ansi.org/standards/nace/ansinacemr01032015iso17945
A25: R15 | B25: 국제 코드 | C25: API RP 941 고온 수소 환경 강재(Nelson Curve, HTHA) | D25: 8th Ed. 2016 + Addendum 1 (2020) | E25: A | F25: https://www.dinmedia.de/en/technical-rule/api-rp-941/328516281 | G25: 9판(시간 의존 Nelson Curve) 발행 여부 미확인
A26: R16 | B26: 국제 코드 | C26: API RP 571 손상 메커니즘 (CUI, 염화물 SCC 등) | D26: 3rd Ed. 2020 | E26: A | F26: https://www.api.org/-/media/Files/Certification/ICP/ICP-Certification-Programs/653/2026%20files/March%202027_653_Publications%20Effectivity%20sheet_final.pdf
A27: R17 | B27: 국제 코드 | C27: API Std 598 밸브 검사·시험 | D27: 11th Ed. 2023 | E27: A | F27: https://eshop.normservis.sk/norma/apistd-598-1.2.2023.html
A28: R18 | B28: 국제 코드 | C28: API Spec 6D 파이프라인·배관 밸브 | D28: 25th Ed. (2023.10) | E28: A | F28: https://www.api.org/products-and-services/standards/important-standards-announcements/spec6d
A29: R19 | B29: 국제 코드 | C29: API Std 607 1/4회전 밸브 화재시험 (Fire-safe) | D29: 8th Ed. 2022 | E29: A | F29: https://eshop.normservis.sk/norma/apistd-607-ed-8-1.10.2022.html
A30: R20 | B30: 국제 코드 | C30: ISO 15848-1 산업용 밸브 탈루 배출(Fugitive Emission) | D30: ISO 15848-1:2015 + Amd 1:2017 | E30: A | F30: https://www.iso.org/standard/61441.html
A31: R21 | B31: 국제 코드 | C31: EN 10204 금속제품 검사문서 (3.1: 제조사 독립 검사, 3.2: 구매자/제3자 공동 확인) | D31: EN 10204:2004 | E31: B | F31: https://wermac.org/din/en10204.html
A32: R22 | B32: 국제 코드 | C32: API RP 2201 안전한 Hot Tapping | D32: 5th Ed. 2003 (2020 재등재) | E32: A | F32: https://online.standard.no/en/api-rp-2201
A33: R23 | B33: 국제 코드 | C33: API RP 2218 석유화학 공장 내화피복(Fireproofing) | D33: 3rd Ed. 2013 (R2020) | E33: A | F33: https://eshop.normservis.sk/norma/apirp-2218-ed-3-1.3.2020.html
A34: R24 | B34: 국제 코드 | C34: API Std 521 압력방출·감압 시스템 | D34: 7th Ed. 2020 (Errata 2022) | E34: A | F34: https://eshop.normservis.sk/norma/apistd-521-31.5.2020.html
A35: R25 | B35: 국제 코드 | C35: API Std 537 Flare 상세 사양 | D35: 3rd Ed. (이후 개정 상태 미확인) | E35: B | F35: https://online.standard.no/nb/api-std-537-8
A36: R26 | B36: 국제 코드 | C36: IEC 60079-10-1 폭발위험장소 구분 (가스) | D36: Ed. 3.0, 2020 | E36: A | F36: https://webstore.iec.ch/publication/63327 | G36: KS C IEC 60079-10-1 판 미확인
A37: R27 | B37: 국제 코드 | C37: API RP 505 폭발위험장소 구분 (Zone 방식) | D37: 2025.1 판 (2018판 대체) | E37: A | F37: https://dinmedia.de/en/technical-rule/api-rp-505/296066690
